Workbook
Name hr_ini: #REF!
Name hr_ini: #REF!
Name hr_ini: #REF!
Name hr_ini: #REF!
Name hr_ini: #REF!
Name hr_limite: #REF!
Name hr_limite: #REF!
Name hr_limite: #REF!
Name hr_limite: #REF!
Name hr_limite: #REF!
Name lista_causa: #REF!
Name lista_causa: [5]!causa_raiz[Causa Raiz]
Name lista_causa: #REF!
Name lista_causa: #REF!
Name lista_causa: #REF!
Name logo: #REF!
Name logo: #REF!
Name logo: #REF!
Name logo: #REF!
Name logo: #REF!
Name nr_salas: #REF!
Name nr_salas: #REF!
Name nr_salas: #REF!
Name nr_salas: #REF!
Name nr_salas: #REF!
Name produtos: [6]Cad!$B$12:$B$511
Name responsável: #REF!
Name responsável: [5]!plano[QUEM]
Name responsável: #REF!
Name responsável: #REF!
Name responsável: #REF!

Sheet HOME
B2: COCKPIT: | E2: NOME DO PILAR | N2: LOGO DA EMPRESA
B4: 1 | C4: MATRIZ DE INDICADORES DA ÁREA | E4: 2 | F4: ANÁLISE GRÁFICA DOS INDICADORES | H4: 3 | I4: MATRIZ DE PROCESSOS PRIORITÁRIOS | K4: 4 | L4: MATRIZ DE CARGOS E FUNÇÕES DA ÁREA | N4: 5 | O4: PLANO DE AÇÃO ESPECÍFICO DA ÁREA
B6: ENTRADAS: (O QUE A ÁREA RECEBE) SAÍDAS: (O QUE A ÁREA ENTREGA)

Sheet 1.
B2: < HOME | C2: 1. MATRIZ DE INDICADORES | D2: =HOME!E2 -> NOME DO PILAR | J2: JANEIRO | O2: FEVEREIRO | T2: MARÇO | Y2: ABRIL | AD2: MAIO | AI2: JUNHO | AN2: JULHO | AS2: AGOSTO | AX2: SETEMBRO | BC2: OUTUBRO | BH2: NOVEMBRO | BM2: DEZEMBRO | BR2: ANO
B4: # | C4: INDICADOR | D4: TIPO MEDIDA | E4: STATUS | F4: RESPONSÁVEL PELA MEDIÇÃO E COLETA | H4: MELHOR | J4: META | K4: REALIZADO | L4: DESVIO | M4: STATUS | O4: META | P4: REALIZADO | Q4: DESVIO | R4: STATUS | T4: META | U4: REALIZADO | V4: DESVIO | W4: STATUS | Y4: META | Z4: REALIZADO | AA4: DESVIO | AB4: STATUS | AD4: META | AE4: REALIZADO | AF4: DESVIO | AG4: STATUS | AI4: META | AJ4: REALIZADO | AK4: DESVIO | AL4: STATUS | AN4: META | AO4: REALIZADO | AP4: DESVIO | AQ4: STATUS | AS4: META | AT4: REALIZADO | AU4: DESVIO | AV4: STATUS | AX4: META | AY4: REALIZADO | AZ4: DESVIO | BA4: STATUS | BC4: META | BD4: REALIZADO | BE4: DESVIO | BF4: STATUS | BH4: META | BI4: REALIZADO | BJ4: DESVIO | BK4: STATUS | BM4: META | BN4: REALIZADO | BO4: DESVIO | BP4: STATUS | BR4: META | BS4: REALIZADO | BT4: DESVIO | BU4: STATUS
B6: 1 | D6: R$ | E6: É MEDIDO, MAS NÃO É CONFIÁVEL | F6: NOME DE 1 PESSOA | H6: ↑ | L6: =IF(H6="↓",J6-K6,IF(H6="↑",K6-J6,0)) -> 0 | M6: {=_xlfn.IFS($H$6="↑",IF(K6>=J6,3,IF(K6>=J6*80%,2,1)),$H$6="↓",IF(K6>J6,1,IF(K6>=J6*80%,3,3)))} -> 3 | O6: =$J$6 -> 0 | Q6: =IF($H$6="↓",O6-P6,IF($H$6="↑",P6-O6,0)) -> 0 | R6: {=_xlfn.IFS($H$6="↑",IF(P6>=O6,3,IF(P6>=O6*80%,2,1)),$H$6="↓",IF(P6>O6,1,IF(P6>=O6*80%,3,3)))} -> 3 | T6: =$J$6 -> 0 | U6: 13000 | V6: =IF($H$6="↓",T6-U6,IF($H$6="↑",U6-T6,0)) -> 13000 | W6: {=_xlfn.IFS($H$6="↑",IF(U6>=T6,3,IF(U6>=T6*80%,2,1)),$H$6="↓",IF(U6>T6,1,IF(U6>=T6*80%,3,3)))} -> 3 | Y6: =$J$6 -> 0 | AA6: =IF($H$6="↓",Y6-Z6,IF($H$6="↑",Z6-Y6,0)) -> 0 | AB6: {=_xlfn.IFS($H$6="↑",IF(Z6>=Y6,3,IF(Z6>=Y6*80%,2,1)),$H$6="↓",IF(Z6>Y6,1,IF(Z6>=Y6*80%,3,3)))} -> 3 | AD6: =$J$6 -> 0 | AF6: =IF($H$6="↓",AD6-AE6,IF($H$6="↑",AE6-AD6,0)) -> 0 | AG6: {=_xlfn.IFS($H$6="↑",IF(AE6>=AD6,3,IF(AE6>=AD6*80%,2,1)),$H$6="↓",IF(AE6>AD6,1,IF(AE6>=AD6*80%,3,3)))} -> 3 | AI6: =$J$6 -> 0 | AK6: =IF($H$6="↓",AI6-AJ6,IF($H$6="↑",AJ6-AI6,0)) -> 0 | AL6: {=_xlfn.IFS($H$6="↑",IF(AJ6>=AI6,3,IF(AJ6>=AI6*80%,2,1)),$H$6="↓",IF(AJ6>AI6,1,IF(AJ6>=AI6*80%,3,3)))} -> 3 | AN6: =$J$6 -> 0 | AP6: =IF($H$6="↓",AN6-AO6,IF($H$6="↑",AO6-AN6,0)) -> 0 | AQ6: {=_xlfn.IFS($H$6="↑",IF(AO6>=AN6,3,IF(AO6>=AN6*80%,2,1)),$H$6="↓",IF(AO6>AN6,1,IF(AO6>=AN6*80%,3,3)))} -> 3 | AS6: =$J$6 -> 0 | AU6: =IF($H$6="↓",AS6-AT6,IF($H$6="↑",AT6-AS6,0)) -> 0 | AV6: {=_xlfn.IFS($H$6="↑",IF(AT6>=AS6,3,IF(AT6>=AS6*80%,2,1)),$H$6="↓",IF(AT6>AS6,1,IF(AT6>=AS6*80%,3,3)))} -> 3 | AX6: =$J$6 -> 0 | AZ6: =IF($H$6="↓",AX6-AY6,IF($H$6="↑",AY6-AX6,0)) -> 0 | BA6: {=_xlfn.IFS($H$6="↑",IF(AY6>=AX6,3,IF(AY6>=AX6*80%,2,1)),$H$6="↓",IF(AY6>AX6,1,IF(AY6>=AX6*80%,3,3)))} -> 3 | BC6: =$J$6 -> 0 | BE6: =IF($H$6="↓",BC6-BD6,IF($H$6="↑",BD6-BC6,0)) -> 0 | BF6: {=_xlfn.IFS($H$6="↑",IF(BD6>=BC6,3,IF(BD6>=BC6*80%,2,1)),$H$6="↓",IF(BD6>BC6,1,IF(BD6>=BC6*80%,3,3)))} -> 3 | BH6: =$J$6 -> 0 | BJ6: =IF($H$6="↓",BH6-BI6,IF($H$6="↑",BI6-BH6,0)) -> 0 | BK6: {=_xlfn.IFS($H$6="↑",IF(BI6>=BH6,3,IF(BI6>=BH6*80%,2,1)),$H$6="↓",IF(BI6>BH6,1,IF(BI6>=BH6*80%,3,3)))} -> 3 | BM6: =$J$6 -> 0 | BO6: =IF($H$6="↓",BM6-BN6,IF($H$6="↑",BN6-BM6,0)) -> 0 | BP6: {=_xlfn.IFS($H$6="↑",IF(BN6>=BM6,3,IF(BN6>=BM6*80%,2,1)),$H$6="↓",IF(BN6>BM6,1,IF(BN6>=BM6*80%,3,3)))} -> 3 | BR6: =SUM(J6,O6,T6,Y6,AD6,AI6,AN6,AS6,AX6,BC6,BH6,BM6) -> 0 | BS6: =SUM(K6,P6,U6,Z6,AE6,AJ6,AO6,AT6,AY6,BD6,BI6,BN6) -> 13000 | BT6: =IF($H$6="↓",BR6-BS6,IF($H$6="↑",BS6-BR6,0)) -> 13000 | BU6: {=_xlfn.IFS($H$6="↑",IF(BS6>=BR6,3,IF(BS6>=BR6*80%,2,1)),$H$6="↓",IF(BS6>BR6,1,IF(BS6>=BR6*80%,3,3)))} -> 3
B7: 2 | D7: % | E7: NÃO É MEDIDO | F7: NOME DE 1 PESSOA | H7: ↑ | L7: =IF(H7="↓",J7-K7,IF(H7="↑",K7-J7,0)) -> 0 | M7: {=_xlfn.IFS($H$7="↑",IF(K7>=J7,3,IF(K7>=J7*80%,2,1)),$H$7="↓",IF(K7>J7,1,IF(K7>=J7*80%,3,3)))} -> 3 | O7: =$J$7 -> 0 | Q7: =IF($H$7="↓",O7-P7,IF($H$7="↑",P7-O7,0)) -> 0 | R7: {=_xlfn.IFS($H$7="↑",IF(P7>=O7,3,IF(P7>=O7*80%,2,1)),$H$7="↓",IF(P7>O7,1,IF(P7>=O7*80%,3,3)))} -> 3 | T7: =$J$7 -> 0 | V7: =IF($H$7="↓",T7-U7,IF($H$7="↑",U7-T7,0)) -> 0 | W7: {=_xlfn.IFS($H$7="↑",IF(U7>=T7,3,IF(U7>=T7*80%,2,1)),$H$7="↓",IF(U7>T7,1,IF(U7>=T7*80%,3,3)))} -> 3 | Y7: =$J$7 -> 0 | AA7: =IF($H$7="↓",Y7-Z7,IF($H$7="↑",Z7-Y7,0)) -> 0 | AB7: {=_xlfn.IFS($H$7="↑",IF(Z7>=Y7,3,IF(Z7>=Y7*80%,2,1)),$H$7="↓",IF(Z7>Y7,1,IF(Z7>=Y7*80%,3,3)))} -> 3 | AD7: =$J$7 -> 0 | AF7: =IF($H$7="↓",AD7-AE7,IF($H$7="↑",AE7-AD7,0)) -> 0 | AG7: {=_xlfn.IFS($H$7="↑",IF(AE7>=AD7,3,IF(AE7>=AD7*80%,2,1)),$H$7="↓",IF(AE7>AD7,1,IF(AE7>=AD7*80%,3,3)))} -> 3 | AI7: =$J$7 -> 0 | AK7: =IF($H$7="↓",AI7-AJ7,IF($H$7="↑",AJ7-AI7,0)) -> 0 | AL7: {=_xlfn.IFS($H$7="↑",IF(AJ7>=AI7,3,IF(AJ7>=AI7*80%,2,1)),$H$7="↓",IF(AJ7>AI7,1,IF(AJ7>=AI7*80%,3,3)))} -> 3 | AN7: =$J$7 -> 0 | AP7: =IF($H$7="↓",AN7-AO7,IF($H$7="↑",AO7-AN7,0)) -> 0 | AQ7: {=_xlfn.IFS($H$7="↑",IF(AO7>=AN7,3,IF(AO7>=AN7*80%,2,1)),$H$7="↓",IF(AO7>AN7,1,IF(AO7>=AN7*80%,3,3)))} -> 3 | AS7: =$J$7 -> 0 | AU7: =IF($H$7="↓",AS7-AT7,IF($H$7="↑",AT7-AS7,0)) -> 0 | AV7: {=_xlfn.IFS($H$7="↑",IF(AT7>=AS7,3,IF(AT7>=AS7*80%,2,1)),$H$7="↓",IF(AT7>AS7,1,IF(AT7>=AS7*80%,3,3)))} -> 3 | AX7: =$J$7 -> 0 | AZ7: =IF($H$7="↓",AX7-AY7,IF($H$7="↑",AY7-AX7,0)) -> 0 | BA7: {=_xlfn.IFS($H$7="↑",IF(AY7>=AX7,3,IF(AY7>=AX7*80%,2,1)),$H$7="↓",IF(AY7>AX7,1,IF(AY7>=AX7*80%,3,3)))} -> 3 | BC7: =$J$7 -> 0 | BE7: =IF($H$6="↓",BC7-BD7,IF($H$6="↑",BD7-BC7,0)) -> 0 | BF7: {=_xlfn.IFS($H$7="↑",IF(BD7>=BC7,3,IF(BD7>=BC7*80%,2,1)),$H$7="↓",IF(BD7>BC7,1,IF(BD7>=BC7*80%,3,3)))} -> 3 | BH7: =$J$7 -> 0 | BJ7: =IF($H$6="↓",BH7-BI7,IF($H$6="↑",BI7-BH7,0)) -> 0 | BK7: {=_xlfn.IFS($H$7="↑",IF(BI7>=BH7,3,IF(BI7>=BH7*80%,2,1)),$H$7="↓",IF(BI7>BH7,1,IF(BI7>=BH7*80%,3,3)))} -> 3 | BM7: =$J$7 -> 0 | BO7: =IF($H$7="↓",BM7-BN7,IF($H$7="↑",BN7-BM7,0)) -> 0 | BP7: {=_xlfn.IFS($H$7="↑",IF(BN7>=BM7,3,IF(BN7>=BM7*80%,2,1)),$H$7="↓",IF(BN7>BM7,1,IF(BN7>=BM7*80%,3,3)))} -> 3 | BR7: =SUM(J7,O7,T7,Y7,AD7,AI7,AN7,AS7,AX7,BC7,BH7,BM7) -> 0 | BS7: =SUM(K7,P7,U7,Z7,AE7,AJ7,AO7,AT7,AY7,BD7,BI7,BN7) -> 0 | BT7: =IF($H$7="↓",BR7-BS7,IF($H$7="↑",BS7-BR7,0)) -> 0 | BU7: {=_xlfn.IFS($H$7="↑",IF(BS7>=BR7,3,IF(BS7>=BR7*80%,2,1)),$H$7="↓",IF(BS7>BR7,1,IF(BS7>=BR7*80%,3,3)))} -> 3
B8: 3 | D8: Tempo | E8: É MEDIDO, MAS NÃO É CONFIÁVEL | F8: NOME DE 1 PESSOA | H8: ↓ | L8: =IF(H8="↓",J8-K8,IF(H8="↑",K8-J8,0)) -> 0 | M8: {=_xlfn.IFS($H$8="↑",IF(K8>=J8,3,IF(K8>=J8*80%,2,1)),$H$8="↓",IF(K8>J8,1,IF(K8>=J8*80%,3,3)))} -> 3 | O8: =$J$8 -> 0 | Q8: =IF($H$8="↓",O8-P8,IF($H$8="↑",P8-O8,0)) -> 0 | R8: {=_xlfn.IFS($H$8="↑",IF(P8>=O8,3,IF(P8>=O8*80%,2,1)),$H$8="↓",IF(P8>O8,1,IF(P8>=O8*80%,3,3)))} -> 3 | T8: =$J$8 -> 0 | V8: =IF($H$8="↓",T8-U8,IF($H$8="↑",U8-T8,0)) -> 0 | W8: {=_xlfn.IFS($H$8="↑",IF(U8>=T8,3,IF(U8>=T8*80%,2,1)),$H$8="↓",IF(U8>T8,1,IF(U8>=T8*80%,3,3)))} -> 3 | Y8: =$J$8 -> 0 | AA8: =IF($H$8="↓",Y8-Z8,IF($H$8="↑",Z8-Y8,0)) -> 0 | AB8: {=_xlfn.IFS($H$8="↑",IF(Z8>=Y8,3,IF(Z8>=Y8*80%,2,1)),$H$8="↓",IF(Z8>Y8,1,IF(Z8>=Y8*80%,3,3)))} -> 3 | AD8: =$J$8 -> 0 | AF8: =IF($H$8="↓",AD8-AE8,IF($H$8="↑",AE8-AD8,0)) -> 0 | AG8: {=_xlfn.IFS($H$8="↑",IF(AE8>=AD8,3,IF(AE8>=AD8*80%,2,1)),$H$8="↓",IF(AE8>AD8,1,IF(AE8>=AD8*80%,3,3)))} -> 3 | AI8: =$J$8 -> 0 | AK8: =IF($H$8="↓",AI8-AJ8,IF($H$8="↑",AJ8-AI8,0)) -> 0 | AL8: {=_xlfn.IFS($H$8="↑",IF(AJ8>=AI8,3,IF(AJ8>=AI8*80%,2,1)),$H$8="↓",IF(AJ8>AI8,1,IF(AJ8>=AI8*80%,3,3)))} -> 3 | AN8: =$J$8 -> 0 | AP8: =IF($H$8="↓",AN8-AO8,IF($H$8="↑",AO8-AN8,0)) -> 0 | AQ8: {=_xlfn.IFS($H$8="↑",IF(AO8>=AN8,3,IF(AO8>=AN8*80%,2,1)),$H$8="↓",IF(AO8>AN8,1,IF(AO8>=AN8*80%,3,3)))} -> 3 | AS8: =$J$8 -> 0 | AU8: =IF($H$8="↓",AS8-AT8,IF($H$8="↑",AT8-AS8,0)) -> 0 | AV8: {=_xlfn.IFS($H$8="↑",IF(AT8>=AS8,3,IF(AT8>=AS8*80%,2,1)),$H$8="↓",IF(AT8>AS8,1,IF(AT8>=AS8*80%,3,3)))} -> 3 | AX8: =$J$8 -> 0 | AZ8: =IF($H$8="↓",AX8-AY8,IF($H$8="↑",AY8-AX8,0)) -> 0 | BA8: {=_xlfn.IFS($H$8="↑",IF(AY8>=AX8,3,IF(AY8>=AX8*80%,2,1)),$H$8="↓",IF(AY8>AX8,1,IF(AY8>=AX8*80%,3,3)))} -> 3 | BC8: =$J$8 -> 0 | BE8: =IF($H$8="↓",BC8-BD8,IF($H$8="↑",BD8-BC8,0)) -> 0 | BF8: {=_xlfn.IFS($H$8="↑",IF(BD8>=BC8,3,IF(BD8>=BC8*80%,2,1)),$H$8="↓",IF(BD8>BC8,1,IF(BD8>=BC8*80%,3,3)))} -> 3 | BH8: =$J$8 -> 0 | BJ8: =IF($H$8="↓",BH8-BI8,IF($H$8="↑",BI8-BH8,0)) -> 0 | BK8: {=_xlfn.IFS($H$8="↑",IF(BI8>=BH8,3,IF(BI8>=BH8*80%,2,1)),$H$8="↓",IF(BI8>BH8,1,IF(BI8>=BH8*80%,3,3)))} -> 3 | BM8: =$J$8 -> 0 | BO8: =IF($H$8="↓",BM8-BN8,IF($H$8="↑",BN8-BM8,0)) -> 0 | BP8: {=_xlfn.IFS($H$8="↑",IF(BN8>=BM8,3,IF(BN8>=BM8*80%,2,1)),$H$8="↓",IF(BN8>BM8,1,IF(BN8>=BM8*80%,3,3)))} -> 3 | BR8: =SUM(J8,O8,T8,Y8,AD8,AI8,AN8,AS8,AX8,BC8,BH8,BM8) -> 0 | BS8: =SUM(K8,P8,U8,Z8,AE8,AJ8,AO8,AT8,AY8,BD8,BI8,BN8) -> 0 | BT8: =IF($H$8="↓",BR8-BS8,IF($H$8="↑",BS8-BR8,0)) -> 0 | BU8: {=_xlfn.IFS($H$8="↑",IF(BS8>=BR8,3,IF(BS8>=BR8*80%,2,1)),$H$8="↓",IF(BS8>BR8,1,IF(BS8>=BR8*80%,3,3)))} -> 3
B9: 4 | D9: R$ | E9: MEDIDO E CONFIÁVEL | F9: NOME DE 1 PESSOA | H9: ↑ | L9: =IF(H9="↓",J9-K9,IF(H9="↑",K9-J9,0)) -> 0 | M9: {=_xlfn.IFS($H$9="↑",IF(K9>=J9,3,IF(K9>=J9*80%,2,1)),$H$9="↓",IF(K9>J9,1,IF(K9>=J9*80%,3,3)))} -> 3 | O9: =$J$9 -> 0 | Q9: =IF($H$9="↓",O9-P9,IF($H$9="↑",P9-O9,0)) -> 0 | R9: {=_xlfn.IFS($H$9="↑",IF(P9>=O9,3,IF(P9>=O9*80%,2,1)),$H$9="↓",IF(P9>O9,1,IF(P9>=O9*80%,3,3)))} -> 3 | T9: =$J$9 -> 0 | V9: =IF($H$9="↓",T9-U9,IF($H$9="↑",U9-T9,0)) -> 0 | W9: {=_xlfn.IFS($H$9="↑",IF(U9>=T9,3,IF(U9>=T9*80%,2,1)),$H$9="↓",IF(U9>T9,1,IF(U9>=T9*80%,3,3)))} -> 3 | Y9: =$J$9 -> 0 | AA9: =IF($H$9="↓",Y9-Z9,IF($H$9="↑",Z9-Y9,0)) -> 0 | AB9: {=_xlfn.IFS($H$9="↑",IF(Z9>=Y9,3,IF(Z9>=Y9*80%,2,1)),$H$9="↓",IF(Z9>Y9,1,IF(Z9>=Y9*80%,3,3)))} -> 3 | AD9: =$J$9 -> 0 | AF9: =IF($H$9="↓",AD9-AE9,IF($H$9="↑",AE9-AD9,0)) -> 0 | AG9: {=_xlfn.IFS($H$9="↑",IF(AE9>=AD9,3,IF(AE9>=AD9*80%,2,1)),$H$9="↓",IF(AE9>AD9,1,IF(AE9>=AD9*80%,3,3)))} -> 3 | AI9: =$J$9 -> 0 | AK9: =IF($H$9="↓",AI9-AJ9,IF($H$9="↑",AJ9-AI9,0)) -> 0 | AL9: {=_xlfn.IFS($H$9="↑",IF(AJ9>=AI9,3,IF(AJ9>=AI9*80%,2,1)),$H$9="↓",IF(AJ9>AI9,1,IF(AJ9>=AI9*80%,3,3)))} -> 3 | AN9: =$J$9 -> 0 | AP9: =IF($H$9="↓",AN9-AO9,IF($H$9="↑",AO9-AN9,0)) -> 0 | AQ9: {=_xlfn.IFS($H$9="↑",IF(AO9>=AN9,3,IF(AO9>=AN9*80%,2,1)),$H$9="↓",IF(AO9>AN9,1,IF(AO9>=AN9*80%,3,3)))} -> 3 | AS9: =$J$9 -> 0 | AU9: =IF($H$9="↓",AS9-AT9,IF($H$9="↑",AT9-AS9,0)) -> 0 | AV9: {=_xlfn.IFS($H$9="↑",IF(AT9>=AS9,3,IF(AT9>=AS9*80%,2,1)),$H$9="↓",IF(AT9>AS9,1,IF(AT9>=AS9*80%,3,3)))} -> 3 | AX9: =$J$9 -> 0 | AZ9: =IF($H$9="↓",AX9-AY9,IF($H$9="↑",AY9-AX9,0)) -> 0 | BA9: {=_xlfn.IFS($H$9="↑",IF(AY9>=AX9,3,IF(AY9>=AX9*80%,2,1)),$H$9="↓",IF(AY9>AX9,1,IF(AY9>=AX9*80%,3,3)))} -> 3 | BC9: =$J$9 -> 0 | BE9: =IF($H$9="↓",BC9-BD9,IF($H$9="↑",BD9-BC9,0)) -> 0 | BF9: {=_xlfn.IFS($H$9="↑",IF(BD9>=BC9,3,IF(BD9>=BC9*80%,2,1)),$H$9="↓",IF(BD9>BC9,1,IF(BD9>=BC9*80%,3,3)))} -> 3 | BH9: =$J$9 -> 0 | BJ9: =IF($H$9="↓",BH9-BI9,IF($H$9="↑",BI9-BH9,0)) -> 0 | BK9: {=_xlfn.IFS($H$9="↑",IF(BI9>=BH9,3,IF(BI9>=BH9*80%,2,1)),$H$9="↓",IF(BI9>BH9,1,IF(BI9>=BH9*80%,3,3)))} -> 3 | BM9: =$J$9 -> 0 | BO9: =IF($H$9="↓",BM9-BN9,IF($H$9="↑",BN9-BM9,0)) -> 0 | BP9: {=_xlfn.IFS($H$9="↑",IF(BN9>=BM9,3,IF(BN9>=BM9*80%,2,1)),$H$9="↓",IF(BN9>BM9,1,IF(BN9>=BM9*80%,3,3)))} -> 3 | BR9: =SUM(J9,O9,T9,Y9,AD9,AI9,AN9,AS9,AX9,BC9,BH9,BM9) -> 0 | BS9: =SUM(K9,P9,U9,Z9,AE9,AJ9,AO9,AT9,AY9,BD9,BI9,BN9) -> 0 | BT9: =IF($H$9="↓",BR9-BS9,IF($H$9="↑",BS9-BR9,0)) -> 0 | BU9: {=_xlfn.IFS($H$9="↑",IF(BS9>=BR9,3,IF(BS9>=BR9*80%,2,1)),$H$9="↓",IF(BS9>BR9,1,IF(BS9>=BR9*80%,3,3)))} -> 3
B10: 5 | D10: Qnt. | E10: É MEDIDO, MAS NÃO É CONFIÁVEL | F10: NOME DE 1 PESSOA | H10: ↑ | L10: =IF(H10="↓",J10-K10,IF(H10="↑",K10-J10,0)) -> 0 | M10: {=_xlfn.IFS($H$10="↑",IF(K10>=J10,3,IF(K10>=J10*80%,2,1)),$H$10="↓",IF(K10>J10,1,IF(K10>=J10*80%,3,3)))} -> 3 | O10: =$J$10 -> 0 | Q10: =IF($H$10="↓",O10-P10,IF($H$10="↑",P10-O10,0)) -> 0 | R10: {=_xlfn.IFS($H$10="↑",IF(P10>=O10,3,IF(P10>=O10*80%,2,1)),$H$10="↓",IF(P10>O10,1,IF(P10>=O10*80%,3,3)))} -> 3 | T10: =$J$10 -> 0 | V10: =IF($H$10="↓",T10-U10,IF($H$10="↑",U10-T10,0)) -> 0 | W10: {=_xlfn.IFS($H$10="↑",IF(U10>=T10,3,IF(U10>=T10*80%,2,1)),$H$10="↓",IF(U10>T10,1,IF(U10>=T10*80%,3,3)))} -> 3 | Y10: =$J$10 -> 0 | AA10: =IF($H$10="↓",Y10-Z10,IF($H$10="↑",Z10-Y10,0)) -> 0 | AB10: {=_xlfn.IFS($H$10="↑",IF(Z10>=Y10,3,IF(Z10>=Y10*80%,2,1)),$H$10="↓",IF(Z10>Y10,1,IF(Z10>=Y10*80%,3,3)))} -> 3 | AD10: =$J$10 -> 0 | AF10: =IF($H$10="↓",AD10-AE10,IF($H$10="↑",AE10-AD10,0)) -> 0 | AG10: {=_xlfn.IFS($H$10="↑",IF(AE10>=AD10,3,IF(AE10>=AD10*80%,2,1)),$H$10="↓",IF(AE10>AD10,1,IF(AE10>=AD10*80%,3,3)))} -> 3 | AI10: =$J$10 -> 0 | AK10: =IF($H$10="↓",AI10-AJ10,IF($H$10="↑",AJ10-AI10,0)) -> 0 | AL10: {=_xlfn.IFS($H$10="↑",IF(AJ10>=AI10,3,IF(AJ10>=AI10*80%,2,1)),$H$10="↓",IF(AJ10>AI10,1,IF(AJ10>=AI10*80%,3,3)))} -> 3 | AN10: =$J$10 -> 0 | AP10: =IF($H$10="↓",AN10-AO10,IF($H$10="↑",AO10-AN10,0)) -> 0 | AQ10: {=_xlfn.IFS($H$10="↑",IF(AO10>=AN10,3,IF(AO10>=AN10*80%,2,1)),$H$10="↓",IF(AO10>AN10,1,IF(AO10>=AN10*80%,3,3)))} -> 3 | AS10: =$J$10 -> 0 | AU10: =IF($H$10="↓",AS10-AT10,IF($H$10="↑",AT10-AS10,0)) -> 0 | AV10: {=_xlfn.IFS($H$10="↑",IF(AT10>=AS10,3,IF(AT10>=AS10*80%,2,1)),$H$10="↓",IF(AT10>AS10,1,IF(AT10>=AS10*80%,3,3)))} -> 3 | AX10: =$J$10 -> 0 | AZ10: =IF($H$10="↓",AX10-AY10,IF($H$10="↑",AY10-AX10,0)) -> 0 | BA10: {=_xlfn.IFS($H$10="↑",IF(AY10>=AX10,3,IF(AY10>=AX10*80%,2,1)),$H$10="↓",IF(AY10>AX10,1,IF(AY10>=AX10*80%,3,3)))} -> 3 | BC10: =$J$10 -> 0 | BE10: =IF($H$10="↓",BC10-BD10,IF($H$10="↑",BD10-BC10,0)) -> 0 | BF10: {=_xlfn.IFS($H$10="↑",IF(BD10>=BC10,3,IF(BD10>=BC10*80%,2,1)),$H$10="↓",IF(BD10>BC10,1,IF(BD10>=BC10*80%,3,3)))} -> 3 | BH10: =$J$10 -> 0 | BJ10: =IF($H$10="↓",BH10-BI10,IF($H$10="↑",BI10-BH10,0)) -> 0 | BK10: {=_xlfn.IFS($H$10="↑",IF(BI10>=BH10,3,IF(BI10>=BH10*80%,2,1)),$H$10="↓",IF(BI10>BH10,1,IF(BI10>=BH10*80%,3,3)))} -> 3 | BM10: =$J$10 -> 0 | BO10: =IF($H$10="↓",BM10-BN10,IF($H$10="↑",BN10-BM10,0)) -> 0 | BP10: {=_xlfn.IFS($H$10="↑",IF(BN10>=BM10,3,IF(BN10>=BM10*80%,2,1)),$H$10="↓",IF(BN10>BM10,1,IF(BN10>=BM10*80%,3,3)))} -> 3 | BR10: =SUM(J10,O10,T10,Y10,AD10,AI10,AN10,AS10,AX10,BC10,BH10,BM10) -> 0 | BS10: =SUM(K10,P10,U10,Z10,AE10,AJ10,AO10,AT10,AY10,BD10,BI10,BN10) -> 0 | BT10: =IF($H$10="↓",BR10-BS10,IF($H$10="↑",BS10-BR10,0)) -> 0 | BU10: {=_xlfn.IFS($H$10="↑",IF(BS10>=BR10,3,IF(BS10>=BR10*80%,2,1)),$H$10="↓",IF(BS10>BR10,1,IF(BS10>=BR10*80%,3,3)))} -> 3
B25: 6 | C25: Indicador 6... | D25: Tempo | E25: NÃO É MEDIDO | F25: NOME DE 1 PESSOA | H25: ↓ | J25: 5 | K25: 5 | L25: =IF(H25="↓",J25-K25,IF(H25="↑",K25-J25,0)) -> 0 | M25: {=_xlfn.IFS($H$9="↑",IF(K25>=J25,3,IF(K25>=J25*80%,2,1)),$H$9="↓",IF(K25>J25,1,IF(K25>=J25*80%,3,3)))} -> 3 | O25: =$J$25 -> 5 | Q25: =IF($H$25="↓",O25-P25,IF($H$25="↑",P25-O25,0)) -> 5 | R25: {=_xlfn.IFS($H$9="↑",IF(P25>=O25,3,IF(P25>=O25*80%,2,1)),$H$9="↓",IF(P25>O25,1,IF(P25>=O25*80%,3,3)))} -> 1 | T25: =$J$25 -> 5 | V25: =IF($H$25="↓",T25-U25,IF($H$25="↑",U25-T25,0)) -> 5 | W25: {=_xlfn.IFS($H$9="↑",IF(U25>=T25,3,IF(U25>=T25*80%,2,1)),$H$9="↓",IF(U25>T25,1,IF(U25>=T25*80%,3,3)))} -> 1 | Y25: =$J$25 -> 5 | AA25: =IF($H$25="↓",Y25-Z25,IF($H$25="↑",Z25-Y25,0)) -> 5 | AB25: {=_xlfn.IFS($H$9="↑",IF(Z25>=Y25,3,IF(Z25>=Y25*80%,2,1)),$H$9="↓",IF(Z25>Y25,1,IF(Z25>=Y25*80%,3,3)))} -> 1 | AD25: =$J$25 -> 5 | AF25: =IF($H$25="↓",AD25-AE25,IF($H$25="↑",AE25-AD25,0)) -> 5 | AG25: {=_xlfn.IFS($H$9="↑",IF(AE25>=AD25,3,IF(AE25>=AD25*80%,2,1)),$H$9="↓",IF(AE25>AD25,1,IF(AE25>=AD25*80%,3,3)))} -> 1 | AI25: =$J$25 -> 5 | AK25: =IF($H$25="↓",AI25-AJ25,IF($H$25="↑",AJ25-AI25,0)) -> 5 | AL25: {=_xlfn.IFS($H$9="↑",IF(AJ25>=AI25,3,IF(AJ25>=AI25*80%,2,1)),$H$9="↓",IF(AJ25>AI25,1,IF(AJ25>=AI25*80%,3,3)))} -> 1 | AN25: =$J$25 -> 5 | AP25: =IF($H$25="↓",AN25-AO25,IF($H$25="↑",AO25-AN25,0)) -> 5 | AQ25: {=_xlfn.IFS($H$9="↑",IF(AO25>=AN25,3,IF(AO25>=AN25*80%,2,1)),$H$9="↓",IF(AO25>AN25,1,IF(AO25>=AN25*80%,3,3)))} -> 1 | AS25: =$J$25 -> 5 | AU25: =IF($H$25="↓",AS25-AT25,IF($H$25="↑",AT25-AS25,0)) -> 5 | AV25: {=_xlfn.IFS($H$9="↑",IF(AT25>=AS25,3,IF(AT25>=AS25*80%,2,1)),$H$9="↓",IF(AT25>AS25,1,IF(AT25>=AS25*80%,3,3)))} -> 1 | AX25: =$J$25 -> 5 | AZ25: =IF($H$25="↓",AX25-AY25,IF($H$25="↑",AY25-AX25,0)) -> 5 | BA25: {=_xlfn.IFS($H$9="↑",IF(AY25>=AX25,3,IF(AY25>=AX25*80%,2,1)),$H$9="↓",IF(AY25>AX25,1,IF(AY25>=AX25*80%,3,3)))} -> 1 | BC25: =$J$25 -> 5 | BE25: =IF($H$25="↓",BC25-BD25,IF($H$25="↑",BD25-BC25,0)) -> 5 | BF25: {=_xlfn.IFS($H$9="↑",IF(BD25>=BC25,3,IF(BD25>=BC25*80%,2,1)),$H$9="↓",IF(BD25>BC25,1,IF(BD25>=BC25*80%,3,3)))} -> 1 | BH25: =$J$25 -> 5 | BJ25: =IF($H$25="↓",BH25-BI25,IF($H$25="↑",BI25-BH25,0)) -> 5 | BK25: {=_xlfn.IFS($H$9="↑",IF(BI25>=BH25,3,IF(BI25>=BH25*80%,2,1)),$H$9="↓",IF(BI25>BH25,1,IF(BI25>=BH25*80%,3,3)))} -> 1 | BM25: =$J$25 -> 5 | BO25: =IF($H$25="↓",BM25-BN25,IF($H$25="↑",BN25-BM25,0)) -> 5 | BP25: {=_xlfn.IFS($H$9="↑",IF(BN25>=BM25,3,IF(BN25>=BM25*80%,2,1)),$H$9="↓",IF(BN25>BM25,1,IF(BN25>=BM25*80%,3,3)))} -> 1 | BR25: =SUM(J25,O25,T25,Y25,AD25,AI25,AN25,AS25,AX25,BC25,BH25,BM25) -> 60 | BS25: =SUM(K25,P25,U25,Z25,AE25,AJ25,AO25,AT25,AY25,BD25,BI25,BN25) -> 5 | BT25: =IF($H$9="↓",BR25-BS25,IF($H$9="↑",BS25-BR25,0)) -> -55 | BU25: {=_xlfn.IFS($H$9="↑",IF(BS25>=BR25,3,IF(BS25>=BR25*80%,2,1)),$H$9="↓",IF(BS25>BR25,1,IF(BS25>=BR25*80%,3,3)))} -> 1
B27: 7 | C27: Indicador 7... | D27: Qnt. | E27: MEDIDO E CONFIÁVEL | F27: NOME DE 1 PESSOA | H27: ↑ | J27: 500 | K27: 500 | L27: =IF(H27="↓",J27-K27,IF(H27="↑",K27-J27,0)) -> 0 | M27: {=_xlfn.IFS($H$9="↑",IF(K27>=J27,3,IF(K27>=J27*80%,2,1)),$H$9="↓",IF(K27>J27,1,IF(K27>=J27*80%,3,3)))} -> 3 | O27: =$J$27 -> 500 | Q27: =IF($H$25="↓",O27-P27,IF($H$25="↑",P27-O27,0)) -> 500 | R27: {=_xlfn.IFS($H$9="↑",IF(P27>=O27,3,IF(P27>=O27*80%,2,1)),$H$9="↓",IF(P27>O27,1,IF(P27>=O27*80%,3,3)))} -> 1 | T27: =$J$27 -> 500 | V27: =IF($H$25="↓",T27-U27,IF($H$25="↑",U27-T27,0)) -> 500 | W27: {=_xlfn.IFS($H$9="↑",IF(U27>=T27,3,IF(U27>=T27*80%,2,1)),$H$9="↓",IF(U27>T27,1,IF(U27>=T27*80%,3,3)))} -> 1 | Y27: =$J$27 -> 500 | AA27: =IF($H$25="↓",Y27-Z27,IF($H$25="↑",Z27-Y27,0)) -> 500 | AB27: {=_xlfn.IFS($H$9="↑",IF(Z27>=Y27,3,IF(Z27>=Y27*80%,2,1)),$H$9="↓",IF(Z27>Y27,1,IF(Z27>=Y27*80%,3,3)))} -> 1 | AD27: =$J$27 -> 500 | AF27: =IF($H$25="↓",AD27-AE27,IF($H$25="↑",AE27-AD27,0)) -> 500 | AG27: {=_xlfn.IFS($H$9="↑",IF(AE27>=AD27,3,IF(AE27>=AD27*80%,2,1)),$H$9="↓",IF(AE27>AD27,1,IF(AE27>=AD27*80%,3,3)))} -> 1 | AI27: =$J$27 -> 500 | AK27: =IF($H$25="↓",AI27-AJ27,IF($H$25="↑",AJ27-AI27,0)) -> 500 | AL27: {=_xlfn.IFS($H$9="↑",IF(AJ27>=AI27,3,IF(AJ27>=AI27*80%,2,1)),$H$9="↓",IF(AJ27>AI27,1,IF(AJ27>=AI27*80%,3,3)))} -> 1 | AN27: =$J$27 -> 500 | AP27: =IF($H$25="↓",AN27-AO27,IF($H$25="↑",AO27-AN27,0)) -> 500 | AQ27: {=_xlfn.IFS($H$9="↑",IF(AO27>=AN27,3,IF(AO27>=AN27*80%,2,1)),$H$9="↓",IF(AO27>AN27,1,IF(AO27>=AN27*80%,3,3)))} -> 1 | AS27: =$J$27 -> 500 | AU27: =IF($H$25="↓",AS27-AT27,IF($H$25="↑",AT27-AS27,0)) -> 500 | AV27: {=_xlfn.IFS($H$9="↑",IF(AT27>=AS27,3,IF(AT27>=AS27*80%,2,1)),$H$9="↓",IF(AT27>AS27,1,IF(AT27>=AS27*80%,3,3)))} -> 1 | AX27: =$J$27 -> 500 | AZ27: =IF($H$25="↓",AX27-AY27,IF($H$25="↑",AY27-AX27,0)) -> 500 | BA27: {=_xlfn.IFS($H$9="↑",IF(AY27>=AX27,3,IF(AY27>=AX27*80%,2,1)),$H$9="↓",IF(AY27>AX27,1,IF(AY27>=AX27*80%,3,3)))} -> 1 | BC27: =$J$27 -> 500 | BE27: =IF($H$25="↓",BC27-BD27,IF($H$25="↑",BD27-BC27,0)) -> 500 | BF27: {=_xlfn.IFS($H$9="↑",IF(BD27>=BC27,3,IF(BD27>=BC27*80%,2,1)),$H$9="↓",IF(BD27>BC27,1,IF(BD27>=BC27*80%,3,3)))} -> 1 | BH27: =$J$27 -> 500 | BJ27: =IF($H$25="↓",BH27-BI27,IF($H$25="↑",BI27-BH27,0)) -> 500 | BK27: {=_xlfn.IFS($H$9="↑",IF(BI27>=BH27,3,IF(BI27>=BH27*80%,2,1)),$H$9="↓",IF(BI27>BH27,1,IF(BI27>=BH27*80%,3,3)))} -> 1 | BM27: =$J$27 -> 500 | BO27: =IF($H$25="↓",BM27-BN27,IF($H$25="↑",BN27-BM27,0)) -> 500 | BP27: {=_xlfn.IFS($H$9="↑",IF(BN27>=BM27,3,IF(BN27>=BM27*80%,2,1)),$H$9="↓",IF(BN27>BM27,1,IF(BN27>=BM27*80%,3,3)))} -> 1 | BR27: =SUM(J27,O27,T27,Y27,AD27,AI27,AN27,AS27,AX27,BC27,BH27,BM27) -> 6000 | BS27: =SUM(K27,P27,U27,Z27,AE27,AJ27,AO27,AT27,AY27,BD27,BI27,BN27) -> 500 | BT27: =IF($H$9="↓",BR27-BS27,IF($H$9="↑",BS27-BR27,0)) -> -5500 | BU27: {=_xlfn.IFS($H$9="↑",IF(BS27>=BR27,3,IF(BS27>=BR27*80%,2,1)),$H$9="↓",IF(BS27>BR27,1,IF(BS27>=BR27*80%,3,3)))} -> 1
B29: 8 | C29: Indicador 8... | D29: R$ | E29: É MEDIDO, MAS NÃO É CONFIÁVEL | F29: NOME DE 1 PESSOA | H29: ↓ | J29: 1000 | K29: 1000 | L29: =IF(H29="↓",J29-K29,IF(H29="↑",K29-J29,0)) -> 0 | M29: {=_xlfn.IFS($H$9="↑",IF(K29>=J29,3,IF(K29>=J29*80%,2,1)),$H$9="↓",IF(K29>J29,1,IF(K29>=J29*80%,3,3)))} -> 3 | O29: =$J$29 -> 1000 | Q29: =IF($H$25="↓",O29-P29,IF($H$25="↑",P29-O29,0)) -> 1000 | R29: {=_xlfn.IFS($H$9="↑",IF(P29>=O29,3,IF(P29>=O29*80%,2,1)),$H$9="↓",IF(P29>O29,1,IF(P29>=O29*80%,3,3)))} -> 1 | T29: =$J$29 -> 1000 | V29: =IF($H$25="↓",T29-U29,IF($H$25="↑",U29-T29,0)) -> 1000 | W29: {=_xlfn.IFS($H$9="↑",IF(U29>=T29,3,IF(U29>=T29*80%,2,1)),$H$9="↓",IF(U29>T29,1,IF(U29>=T29*80%,3,3)))} -> 1 | Y29: =$J$29 -> 1000 | AA29: =IF($H$25="↓",Y29-Z29,IF($H$25="↑",Z29-Y29,0)) -> 1000 | AB29: {=_xlfn.IFS($H$9="↑",IF(Z29>=Y29,3,IF(Z29>=Y29*80%,2,1)),$H$9="↓",IF(Z29>Y29,1,IF(Z29>=Y29*80%,3,3)))} -> 1 | AD29: =$J$29 -> 1000 | AF29: =IF($H$25="↓",AD29-AE29,IF($H$25="↑",AE29-AD29,0)) -> 1000 | AG29: {=_xlfn.IFS($H$9="↑",IF(AE29>=AD29,3,IF(AE29>=AD29*80%,2,1)),$H$9="↓",IF(AE29>AD29,1,IF(AE29>=AD29*80%,3,3)))} -> 1 | AI29: =$J$29 -> 1000 | AK29: =IF($H$25="↓",AI29-AJ29,IF($H$25="↑",AJ29-AI29,0)) -> 1000 | AL29: {=_xlfn.IFS($H$9="↑",IF(AJ29>=AI29,3,IF(AJ29>=AI29*80%,2,1)),$H$9="↓",IF(AJ29>AI29,1,IF(AJ29>=AI29*80%,3,3)))} -> 1 | AN29: =$J$29 -> 1000 | AP29: =IF($H$25="↓",AN29-AO29,IF($H$25="↑",AO29-AN29,0)) -> 1000 | AQ29: {=_xlfn.IFS($H$9="↑",IF(AO29>=AN29,3,IF(AO29>=AN29*80%,2,1)),$H$9="↓",IF(AO29>AN29,1,IF(AO29>=AN29*80%,3,3)))} -> 1 | AS29: =$J$29 -> 1000 | AU29: =IF($H$25="↓",AS29-AT29,IF($H$25="↑",AT29-AS29,0)) -> 1000 | AV29: {=_xlfn.IFS($H$9="↑",IF(AT29>=AS29,3,IF(AT29>=AS29*80%,2,1)),$H$9="↓",IF(AT29>AS29,1,IF(AT29>=AS29*80%,3,3)))} -> 1 | AX29: =$J$29 -> 1000 | AZ29: =IF($H$25="↓",AX29-AY29,IF($H$25="↑",AY29-AX29,0)) -> 1000 | BA29: {=_xlfn.IFS($H$9="↑",IF(AY29>=AX29,3,IF(AY29>=AX29*80%,2,1)),$H$9="↓",IF(AY29>AX29,1,IF(AY29>=AX29*80%,3,3)))} -> 1 | BC29: =$J$29 -> 1000 | BE29: =IF($H$25="↓",BC29-BD29,IF($H$25="↑",BD29-BC29,0)) -> 1000 | BF29: {=_xlfn.IFS($H$9="↑",IF(BD29>=BC29,3,IF(BD29>=BC29*80%,2,1)),$H$9="↓",IF(BD29>BC29,1,IF(BD29>=BC29*80%,3,3)))} -> 1 | BH29: =$J$29 -> 1000 | BJ29: =IF($H$25="↓",BH29-BI29,IF($H$25="↑",BI29-BH29,0)) -> 1000 | BK29: {=_xlfn.IFS($H$9="↑",IF(BI29>=BH29,3,IF(BI29>=BH29*80%,2,1)),$H$9="↓",IF(BI29>BH29,1,IF(BI29>=BH29*80%,3,3)))} -> 1 | BM29: =$J$29 -> 1000 | BO29: =IF($H$25="↓",BM29-BN29,IF($H$25="↑",BN29-BM29,0)) -> 1000 | BP29: {=_xlfn.IFS($H$9="↑",IF(BN29>=BM29,3,IF(BN29>=BM29*80%,2,1)),$H$9="↓",IF(BN29>BM29,1,IF(BN29>=BM29*80%,3,3)))} -> 1 | BR29: =SUM(J29,O29,T29,Y29,AD29,AI29,AN29,AS29,AX29,BC29,BH29,BM29) -> 12000 | BS29: =SUM(K29,P29,U29,Z29,AE29,AJ29,AO29,AT29,AY29,BD29,BI29,BN29) -> 1000 | BT29: =IF($H$9="↓",BR29-BS29,IF($H$9="↑",BS29-BR29,0)) -> -11000 | BU29: {=_xlfn.IFS($H$9="↑",IF(BS29>=BR29,3,IF(BS29>=BR29*80%,2,1)),$H$9="↓",IF(BS29>BR29,1,IF(BS29>=BR29*80%,3,3)))} -> 1
B31: 9 | C31: Indicador 9... | D31: % | E31: MEDIDO E CONFIÁVEL | F31: NOME DE 1 PESSOA | H31: ↑ | J31: 10 | K31: 10 | L31: =IF(H31="↓",J31-K31,IF(H31="↑",K31-J31,0)) -> 0 | M31: {=_xlfn.IFS($H$9="↑",IF(K31>=J31,3,IF(K31>=J31*80%,2,1)),$H$9="↓",IF(K31>J31,1,IF(K31>=J31*80%,3,3)))} -> 3 | O31: =$J$31 -> 10 | Q31: =IF($H$25="↓",O31-P31,IF($H$25="↑",P31-O31,0)) -> 10 | R31: {=_xlfn.IFS($H$9="↑",IF(P31>=O31,3,IF(P31>=O31*80%,2,1)),$H$9="↓",IF(P31>O31,1,IF(P31>=O31*80%,3,3)))} -> 1 | T31: =$J$31 -> 10 | V31: =IF($H$25="↓",T31-U31,IF($H$25="↑",U31-T31,0)) -> 10 | W31: {=_xlfn.IFS($H$9="↑",IF(U31>=T31,3,IF(U31>=T31*80%,2,1)),$H$9="↓",IF(U31>T31,1,IF(U31>=T31*80%,3,3)))} -> 1 | Y31: =$J$31 -> 10 | AA31: =IF($H$25="↓",Y31-Z31,IF($H$25="↑",Z31-Y31,0)) -> 10 | AB31: {=_xlfn.IFS($H$9="↑",IF(Z31>=Y31,3,IF(Z31>=Y31*80%,2,1)),$H$9="↓",IF(Z31>Y31,1,IF(Z31>=Y31*80%,3,3)))} -> 1 | AD31: =$J$31 -> 10 | AF31: =IF($H$25="↓",AD31-AE31,IF($H$25="↑",AE31-AD31,0)) -> 10 | AG31: {=_xlfn.IFS($H$9="↑",IF(AE31>=AD31,3,IF(AE31>=AD31*80%,2,1)),$H$9="↓",IF(AE31>AD31,1,IF(AE31>=AD31*80%,3,3)))} -> 1 | AI31: =$J$31 -> 10 | AK31: =IF($H$25="↓",AI31-AJ31,IF($H$25="↑",AJ31-AI31,0)) -> 10 | AL31: {=_xlfn.IFS($H$9="↑",IF(AJ31>=AI31,3,IF(AJ31>=AI31*80%,2,1)),$H$9="↓",IF(AJ31>AI31,1,IF(AJ31>=AI31*80%,3,3)))} -> 1 | AN31: =$J$31 -> 10 | AP31: =IF($H$25="↓",AN31-AO31,IF($H$25="↑",AO31-AN31,0)) -> 10 | AQ31: {=_xlfn.IFS($H$9="↑",IF(AO31>=AN31,3,IF(AO31>=AN31*80%,2,1)),$H$9="↓",IF(AO31>AN31,1,IF(AO31>=AN31*80%,3,3)))} -> 1 | AS31: =$J$31 -> 10 | AU31: =IF($H$25="↓",AS31-AT31,IF($H$25="↑",AT31-AS31,0)) -> 10 | AV31: {=_xlfn.IFS($H$9="↑",IF(AT31>=AS31,3,IF(AT31>=AS31*80%,2,1)),$H$9="↓",IF(AT31>AS31,1,IF(AT31>=AS31*80%,3,3)))} -> 1 | AX31: =$J$31 -> 10 | AZ31: =IF($H$25="↓",AX31-AY31,IF($H$25="↑",AY31-AX31,0)) -> 10 | BA31: {=_xlfn.IFS($H$9="↑",IF(AY31>=AX31,3,IF(AY31>=AX31*80%,2,1)),$H$9="↓",IF(AY31>AX31,1,IF(AY31>=AX31*80%,3,3)))} -> 1 | BC31: =$J$31 -> 10 | BE31: =IF($H$25="↓",BC31-BD31,IF($H$25="↑",BD31-BC31,0)) -> 10 | BF31: {=_xlfn.IFS($H$9="↑",IF(BD31>=BC31,3,IF(BD31>=BC31*80%,2,1)),$H$9="↓",IF(BD31>BC31,1,IF(BD31>=BC31*80%,3,3)))} -> 1 | BH31: =$J$31 -> 10 | BJ31: =IF($H$25="↓",BH31-BI31,IF($H$25="↑",BI31-BH31,0)) -> 10 | BK31: {=_xlfn.IFS($H$9="↑",IF(BI31>=BH31,3,IF(BI31>=BH31*80%,2,1)),$H$9="↓",IF(BI31>BH31,1,IF(BI31>=BH31*80%,3,3)))} -> 1 | BM31: =$J$31 -> 10 | BO31: =IF($H$25="↓",BM31-BN31,IF($H$25="↑",BN31-BM31,0)) -> 10 | BP31: {=_xlfn.IFS($H$9="↑",IF(BN31>=BM31,3,IF(BN31>=BM31*80%,2,1)),$H$9="↓",IF(BN31>BM31,1,IF(BN31>=BM31*80%,3,3)))} -> 1 | BR31: =SUM(J31,O31,T31,Y31,AD31,AI31,AN31,AS31,AX31,BC31,BH31,BM31) -> 120 | BS31: =SUM(K31,P31,U31,Z31,AE31,AJ31,AO31,AT31,AY31,BD31,BI31,BN31) -> 10 | BT31: =IF($H$9="↓",BR31-BS31,IF($H$9="↑",BS31-BR31,0)) -> -110 | BU31: {=_xlfn.IFS($H$9="↑",IF(BS31>=BR31,3,IF(BS31>=BR31*80%,2,1)),$H$9="↓",IF(BS31>BR31,1,IF(BS31>=BR31*80%,3,3)))} -> 1
B33: 10 | C33: Indicador 10... | D33: Qnt. | E33: NÃO É MEDIDO | F33: NOME DE 1 PESSOA | H33: ↓ | J33: 250 | K33: 250 | L33: =IF(H33="↓",J33-K33,IF(H33="↑",K33-J33,0)) -> 0 | M33: {=_xlfn.IFS($H$9="↑",IF(K33>=J33,3,IF(K33>=J33*80%,2,1)),$H$9="↓",IF(K33>J33,1,IF(K33>=J33*80%,3,3)))} -> 3 | O33: =$J$33 -> 250 | Q33: =IF($H$25="↓",O33-P33,IF($H$25="↑",P33-O33,0)) -> 250 | R33: {=_xlfn.IFS($H$9="↑",IF(P33>=O33,3,IF(P33>=O33*80%,2,1)),$H$9="↓",IF(P33>O33,1,IF(P33>=O33*80%,3,3)))} -> 1 | T33: =$J$33 -> 250 | V33: =IF($H$25="↓",T33-U33,IF($H$25="↑",U33-T33,0)) -> 250 | W33: {=_xlfn.IFS($H$9="↑",IF(U33>=T33,3,IF(U33>=T33*80%,2,1)),$H$9="↓",IF(U33>T33,1,IF(U33>=T33*80%,3,3)))} -> 1 | Y33: =$J$33 -> 250 | AA33: =IF($H$25="↓",Y33-Z33,IF($H$25="↑",Z33-Y33,0)) -> 250 | AB33: {=_xlfn.IFS($H$9="↑",IF(Z33>=Y33,3,IF(Z33>=Y33*80%,2,1)),$H$9="↓",IF(Z33>Y33,1,IF(Z33>=Y33*80%,3,3)))} -> 1 | AD33: =$J$33 -> 250 | AF33: =IF($H$25="↓",AD33-AE33,IF($H$25="↑",AE33-AD33,0)) -> 250 | AG33: {=_xlfn.IFS($H$9="↑",IF(AE33>=AD33,3,IF(AE33>=AD33*80%,2,1)),$H$9="↓",IF(AE33>AD33,1,IF(AE33>=AD33*80%,3,3)))} -> 1 | AI33: =$J$33 -> 250 | AK33: =IF($H$25="↓",AI33-AJ33,IF($H$25="↑",AJ33-AI33,0)) -> 250 | AL33: {=_xlfn.IFS($H$9="↑",IF(AJ33>=AI33,3,IF(AJ33>=AI33*80%,2,1)),$H$9="↓",IF(AJ33>AI33,1,IF(AJ33>=AI33*80%,3,3)))} -> 1 | AN33: =$J$33 -> 250 | AP33: =IF($H$25="↓",AN33-AO33,IF($H$25="↑",AO33-AN33,0)) -> 250 | AQ33: {=_xlfn.IFS($H$9="↑",IF(AO33>=AN33,3,IF(AO33>=AN33*80%,2,1)),$H$9="↓",IF(AO33>AN33,1,IF(AO33>=AN33*80%,3,3)))} -> 1 | AS33: =$J$33 -> 250 | AU33: =IF($H$25="↓",AS33-AT33,IF($H$25="↑",AT33-AS33,0)) -> 250 | AV33: {=_xlfn.IFS($H$9="↑",IF(AT33>=AS33,3,IF(AT33>=AS33*80%,2,1)),$H$9="↓",IF(AT33>AS33,1,IF(AT33>=AS33*80%,3,3)))} -> 1 | AX33: =$J$33 -> 250 | AZ33: =IF($H$25="↓",AX33-AY33,IF($H$25="↑",AY33-AX33,0)) -> 250 | BA33: {=_xlfn.IFS($H$9="↑",IF(AY33>=AX33,3,IF(AY33>=AX33*80%,2,1)),$H$9="↓",IF(AY33>AX33,1,IF(AY33>=AX33*80%,3,3)))} -> 1 | BC33: =$J$33 -> 250 | BE33: =IF($H$25="↓",BC33-BD33,IF($H$25="↑",BD33-BC33,0)) -> 250 | BF33: {=_xlfn.IFS($H$9="↑",IF(BD33>=BC33,3,IF(BD33>=BC33*80%,2,1)),$H$9="↓",IF(BD33>BC33,1,IF(BD33>=BC33*80%,3,3)))} -> 1 | BH33: =$J$33 -> 250 | BJ33: =IF($H$25="↓",BH33-BI33,IF($H$25="↑",BI33-BH33,0)) -> 250 | BK33: {=_xlfn.IFS($H$9="↑",IF(BI33>=BH33,3,IF(BI33>=BH33*80%,2,1)),$H$9="↓",IF(BI33>BH33,1,IF(BI33>=BH33*80%,3,3)))} -> 1 | BM33: =$J$33 -> 250 | BO33: =IF($H$25="↓",BM33-BN33,IF($H$25="↑",BN33-BM33,0)) -> 250 | BP33: {=_xlfn.IFS($H$9="↑",IF(BN33>=BM33,3,IF(BN33>=BM33*80%,2,1)),$H$9="↓",IF(BN33>BM33,1,IF(BN33>=BM33*80%,3,3)))} -> 1 | BR33: =SUM(J33,O33,T33,Y33,AD33,AI33,AN33,AS33,AX33,BC33,BH33,BM33) -> 3000 | BS33: =SUM(K33,P33,U33,Z33,AE33,AJ33,AO33,AT33,AY33,BD33,BI33,BN33) -> 250 | BT33: =IF($H$9="↓",BR33-BS33,IF($H$9="↑",BS33-BR33,0)) -> -2750 | BU33: {=_xlfn.IFS($H$9="↑",IF(BS33>=BR33,3,IF(BS33>=BR33*80%,2,1)),$H$9="↓",IF(BS33>BR33,1,IF(BS33>=BR33*80%,3,3)))} -> 1

Sheet 2.
B2: < HOME | C2: 2. ANÁLISE GRÁFICA DOS INDICADORES | I2: =HOME!E2 -> NOME DO PILAR
B5: Indicad | C5: Mês | D5: Meta | E5: Real
B6: ='1.'!D6 -> R$ | C6: Janeiro | D6: ='1.'!J6 -> 0 | E6: ='1.'!K6 -> 0
B7: =$B$6 -> R$ | C7: Fevereiro | D7: ='1.'!O6 -> 0 | E7: ='1.'!P6 -> 0
B8: =$B$6 -> R$ | C8: Março | D8: ='1.'!T6 -> 0 | E8: ='1.'!U6 -> 13000
B9: =$B$6 -> R$ | C9: Abril | D9: ='1.'!Y6 -> 0 | E9: ='1.'!Z6 -> 0
B10: =$B$6 -> R$ | C10: Maio | D10: ='1.'!AD6 -> 0 | E10: ='1.'!AE6 -> 0
B11: =$B$6 -> R$ | C11: Junho | D11: ='1.'!AI6 -> 0 | E11: ='1.'!AJ6 -> 0
B12: =$B$6 -> R$ | C12: Julho | D12: ='1.'!AN6 -> 0 | E12: ='1.'!AO6 -> 0
B13: =$B$6 -> R$ | C13: Agosto | D13: ='1.'!AS6 -> 0 | E13: ='1.'!AT6 -> 0
B14: =$B$6 -> R$ | C14: Setembro | D14: ='1.'!AX6 -> 0 | E14: ='1.'!AY6 -> 0
B15: =$B$6 -> R$ | C15: Outubro | D15: ='1.'!BC6 -> 0 | E15: ='1.'!BD6 -> 0
B16: =$B$6 -> R$ | C16: Novembro | D16: ='1.'!BH6 -> 0 | E16: ='1.'!BI6 -> 0
B17: =$B$6 -> R$ | C17: Dezembro | D17: ='1.'!BM6 -> 0 | E17: ='1.'!BN6 -> 0
B18: Valores em: | C18: =B6 -> R$ | E18: ='1.'!H6 -> ↑
B20: Indicad | C20: Mês | D20: Meta | E20: Real
B21: ='1.'!D7 -> % | C21: Janeiro | D21: ='1.'!J7 -> 0 | E21: ='1.'!K7 -> 0
B22: =$B$21 -> % | C22: Fevereiro | D22: ='1.'!O7 -> 0 | E22: ='1.'!P7 -> 0
B23: =$B$21 -> % | C23: Março | D23: ='1.'!T7 -> 0 | E23: ='1.'!U7 -> 0
B24: =$B$21 -> % | C24: Abril | D24: ='1.'!Y7 -> 0 | E24: ='1.'!Z7 -> 0
B25: =$B$21 -> % | C25: Maio | D25: ='1.'!AD7 -> 0 | E25: ='1.'!AE7 -> 0
B26: =$B$21 -> % | C26: Junho | D26: ='1.'!AI7 -> 0 | E26: ='1.'!AJ7 -> 0
B27: =$B$21 -> % | C27: Julho | D27: ='1.'!AN7 -> 0 | E27: ='1.'!AO7 -> 0
B28: =$B$21 -> % | C28: Agosto | D28: ='1.'!AS7 -> 0 | E28: ='1.'!AT7 -> 0
B29: =$B$21 -> % | C29: Setembro | D29: ='1.'!AX7 -> 0 | E29: ='1.'!AY7 -> 0
B30: =$B$21 -> % | C30: Outubro | D30: ='1.'!BC7 -> 0 | E30: ='1.'!BD7 -> 0
B31: =$B$21 -> % | C31: Novembro | D31: ='1.'!BH7 -> 0 | E31: ='1.'!BI7 -> 0
B32: =$B$21 -> % | C32: Dezembro | D32: ='1.'!BM7 -> 0 | E32: ='1.'!BN7 -> 0
B33: Valores em: | C33: =B21 -> % | E33: ='1.'!H7 -> ↑
B35: Indicad | C35: Mês | D35: Meta | E35: Real
B36: ='1.'!D8 -> Tempo | C36: Janeiro | D36: ='1.'!J8 -> 0 | E36: ='1.'!K8 -> 0
B37: =$B$36 -> Tempo | C37: Fevereiro | D37: ='1.'!O8 -> 0 | E37: ='1.'!P8 -> 0
B38: =$B$36 -> Tempo | C38: Março | D38: ='1.'!T8 -> 0 | E38: ='1.'!U8 -> 0
B39: =$B$36 -> Tempo | C39: Abril | D39: ='1.'!Y8 -> 0 | E39: ='1.'!Z8 -> 0
B40: =$B$36 -> Tempo | C40: Maio | D40: ='1.'!AD8 -> 0 | E40: ='1.'!AE8 -> 0
B41: =$B$36 -> Tempo | C41: Junho | D41: ='1.'!AI8 -> 0 | E41: ='1.'!AJ8 -> 0
B42: =$B$36 -> Tempo | C42: Julho | D42: ='1.'!AN8 -> 0 | E42: ='1.'!AO8 -> 0
B43: =$B$36 -> Tempo | C43: Agosto | D43: ='1.'!AS8 -> 0 | E43: ='1.'!AT8 -> 0
B44: =$B$36 -> Tempo | C44: Setembro | D44: ='1.'!AX8 -> 0 | E44: ='1.'!AY8 -> 0
B45: =$B$36 -> Tempo | C45: Outubro | D45: ='1.'!BC8 -> 0 | E45: ='1.'!BD8 -> 0
...

Sheet 3.
B2: < HOME | C2: 3. MATRIZ DE PROCESSOS PRIORITÁRIOS | G2: =HOME!E2 -> NOME DO PILAR
B4: # | C4: ROTINAS DO PILAR | D4: NÍVEL CRÍTICO | E4: NOTA ATUAL | G4: STATUS DO MAPEAMENTO | I4: STATUS DO TREINAMENTO/ EXECUÇÃO
B6: 1 | D6: ALTO | E6: 0 | G6: PENDENTE | I6: PENDENTE
B7: 2 | D7: MÉDIO | E7: 1 | G7: EM ANDAMENTO | I7: EM ANDAMENTO
B8: 3 | D8: BAIXO | E8: 2 | G8: CONCLUÍDO | I8: CONCLUÍDO
B9: 4 | D9: BAIXO | E9: 3 | G9: CONCLUÍDO | I9: CONCLUÍDO
B10: 5 | D10: BAIXO | E10: 4 | G10: CONCLUÍDO | I10: CONCLUÍDO
B11: 6 | D11: BAIXO | E11: 5 | G11: CONCLUÍDO | I11: CONCLUÍDO
B12: 7 | D12: BAIXO | E12: 6 | G12: CONCLUÍDO | I12: CONCLUÍDO
B13: 8 | D13: BAIXO | E13: 7 | G13: CONCLUÍDO | I13: CONCLUÍDO
B14: 9 | D14: BAIXO | E14: 8 | G14: CONCLUÍDO | I14: CONCLUÍDO
B15: 10 | D15: BAIXO | E15: 9 | G15: CONCLUÍDO | I15: CONCLUÍDO
B16: 11 | D16: BAIXO | E16: 10 | G16: CONCLUÍDO | I16: CONCLUÍDO
B17: 12 | D17: BAIXO | E17: 10 | G17: CONCLUÍDO | I17: CONCLUÍDO
... B25: 20 | D25: BAIXO | E25: 10 | G25: CONCLUÍDO | I25: CONCLUÍDO

Sheet 4.
B2: < HOME | C2: 4. MATRIZ DE CARGOS E FUNÇÕES | I2: =HOME!E2 -> NOME DO PILAR
B4: # | C4: NOME DO CARGO | D4: NÍVEL CRÍTICO | E4: AUTO AVALIAÇÃO | F4: AVALIAÇÃO DA LIDERANÇA | H4: # | I4: NOME DO CARGO | J4: NÍVEL CRÍTICO | K4: AUTO AVALIAÇÃO | L4: AVALIAÇÃO DA LIDERANÇA | N4: # | O4: NOME DO CARGO | P4: NÍVEL CRÍTICO | Q4: AUTO AVALIAÇÃO | R4: AVALIAÇÃO DA LIDERANÇA | T4: # | U4: NOME DO CARGO | V4: NÍVEL CRÍTICO | W4: AUTO AVALIAÇÃO | X4: AVALIAÇÃO DA LIDERANÇA | Z4: # | AA4: NOME DO CARGO | AB4: NÍVEL CRÍTICO | AC4: AUTO AVALIAÇÃO | AD4: AVALIAÇÃO DA LIDERANÇA
B6: 1 | C6: LISTE AS FUNÇÕES DO CARGO | D6: ALTO | E6: 1 | F6: 10 | H6: 1 | I6: LISTE AS FUNÇÕES DO CARGO | J6: ALTO | K6: 0 | L6: 9 | N6: 1 | O6: LISTE AS FUNÇÕES DO CARGO | P6: ALTO | Q6: 1 | R6: 10 | T6: 1 | U6: LISTE AS FUNÇÕES DO CARGO | V6: ALTO | W6: 1 | X6: 10 | Z6: 1 | AA6: LISTE AS FUNÇÕES DO CARGO | AB6: ALTO | AC6: 1 | AD6: 10
B7: 2 | C7: LISTE AS FUNÇÕES DO CARGO | D7: MÉDIO | E7: 2 | F7: 9 | H7: 2 | I7: LISTE AS FUNÇÕES DO CARGO | J7: MÉDIO | K7: 1 | L7: 8 | N7: 2 | O7: LISTE AS FUNÇÕES DO CARGO | P7: MÉDIO | Q7: 2 | R7: 9 | T7: 2 | U7: LISTE AS FUNÇÕES DO CARGO | V7: MÉDIO | W7: 2 | X7: 9 | Z7: 2 | AA7: LISTE AS FUNÇÕES DO CARGO | AB7: MÉDIO | AC7: 2 | AD7: 9
B8: 3 | C8: LISTE AS FUNÇÕES DO CARGO | D8: BAIXO | E8: 3 | F8: 8 | H8: 3 | I8: LISTE AS FUNÇÕES DO CARGO | J8: BAIXO | K8: 2 | L8: 7 | N8: 3 | O8: LISTE AS FUNÇÕES DO CARGO | P8: BAIXO | Q8: 3 | R8: 8 | T8: 3 | U8: LISTE AS FUNÇÕES DO CARGO | V8: BAIXO | W8: 3 | X8: 8 | Z8: 3 | AA8: LISTE AS FUNÇÕES DO CARGO | AB8: BAIXO | AC8: 3 | AD8: 8
B9: 4 | C9: LISTE AS FUNÇÕES DO CARGO | D9: ALTO | E9: 4 | F9: 7 | H9: 4 | I9: LISTE AS FUNÇÕES DO CARGO | J9: ALTO | K9: 3 | L9: 6 | N9: 4 | O9: LISTE AS FUNÇÕES DO CARGO | P9: ALTO | Q9: 4 | R9: 7 | T9: 4 | U9: LISTE AS FUNÇÕES DO CARGO | V9: ALTO | W9: 4 | X9: 7 | Z9: 4 | AA9: LISTE AS FUNÇÕES DO CARGO | AB9: ALTO | AC9: 4 | AD9: 7
B10: 5 | C10: LISTE AS FUNÇÕES DO CARGO | D10: ALTO | E10: 5 | F10: 6 | H10: 5 | I10: LISTE AS FUNÇÕES DO CARGO | J10: ALTO | K10: 4 | L10: 5 | N10: 5 | O10: LISTE AS FUNÇÕES DO CARGO | P10: ALTO | Q10: 5 | R10: 6 | T10: 5 | U10: LISTE AS FUNÇÕES DO CARGO | V10: ALTO | W10: 5 | X10: 6 | Z10: 5 | AA10: LISTE AS FUNÇÕES DO CARGO | AB10: ALTO | AC10: 5 | AD10: 6
B11: 6 | C11: LISTE AS FUNÇÕES DO CARGO | D11: ALTO | E11: 6 | F11: 5 | H11: 6 | I11: LISTE AS FUNÇÕES DO CARGO | J11: ALTO | K11: 5 | L11: 4 | N11: 6 | O11: LISTE AS FUNÇÕES DO CARGO | P11: ALTO | Q11: 6 | R11: 5 | T11: 6 | U11: LISTE AS FUNÇÕES DO CARGO | V11: ALTO | W11: 6 | X11: 5 | Z11: 6 | AA11: LISTE AS FUNÇÕES DO CARGO | AB11: ALTO | AC11: 6 | AD11: 5
B12: 7 | C12: LISTE AS FUNÇÕES DO CARGO | D12: ALTO | E12: 7 | F12: 4 | H12: 7 | I12: LISTE AS FUNÇÕES DO CARGO | J12: ALTO | K12: 6 | L12: 3 | N12: 7 | O12: LISTE AS FUNÇÕES DO CARGO | P12: ALTO | Q12: 7 | R12: 4 | T12: 7 | U12: LISTE AS FUNÇÕES DO CARGO | V12: ALTO | W12: 7 | X12: 4 | Z12: 7 | AA12: LISTE AS FUNÇÕES DO CARGO | AB12: ALTO | AC12: 7 | AD12: 4
B13: 8 | C13: LISTE AS FUNÇÕES DO CARGO | D13: ALTO | E13: 8 | F13: 3 | H13: 8 | I13: LISTE AS FUNÇÕES DO CARGO | J13: ALTO | K13: 7 | L13: 2 | N13: 8 | O13: LISTE AS FUNÇÕES DO CARGO | P13: ALTO | Q13: 8 | R13: 3 | T13: 8 | U13: LISTE AS FUNÇÕES DO CARGO | V13: ALTO | W13: 8 | X13: 3 | Z13: 8 | AA13: LISTE AS FUNÇÕES DO CARGO | AB13: ALTO | AC13: 8 | AD13: 3
B14: 9 | C14: LISTE AS FUNÇÕES DO CARGO | D14: ALTO | E14: 9 | F14: 2 | H14: 9 | I14: LISTE AS FUNÇÕES DO CARGO | J14: ALTO | K14: 8 | L14: 1 | N14: 9 | O14: LISTE AS FUNÇÕES DO CARGO | P14: ALTO | Q14: 9 | R14: 2 | T14: 9 | U14: LISTE AS FUNÇÕES DO CARGO | V14: ALTO | W14: 9 | X14: 2 | Z14: 9 | AA14: LISTE AS FUNÇÕES DO CARGO | AB14: ALTO | AC14: 9 | AD14: 2
B15: 10 | C15: LISTE AS FUNÇÕES DO CARGO | D15: ALTO | E15: 10 | F15: 1 | H15: 10 | I15: LISTE AS FUNÇÕES DO CARGO | J15: ALTO | K15: 9 | L15: 0 | N15: 10 | O15: LISTE AS FUNÇÕES DO CARGO | P15: ALTO | Q15: 10 | R15: 1 | T15: 10 | U15: LISTE AS FUNÇÕES DO CARGO | V15: ALTO | W15: 10 | X15: 1 | Z15: 10 | AA15: LISTE AS FUNÇÕES DO CARGO | AB15: ALTO | AC15: 10 | AD15: 1
B17: MÉDIO DO CARGO | E17: =IFERROR(AVERAGE(E6:E15),0) -> 5.5 | F17: =IFERROR(AVERAGE(F6:F15),0) -> 5.5 | H17: MÉDIO DO CARGO | K17: =IFERROR(AVERAGE(K6:K15),0) -> 4.5 | L17: =IFERROR(AVERAGE(L6:L15),0) -> 4.5 | N17: MÉDIO DO CARGO | Q17: =IFERROR(AVERAGE(Q6:Q15),0) -> 5.5 | R17: =IFERROR(AVERAGE(R6:R15),0) -> 5.5 | T17: MÉDIO DO CARGO | W17: =IFERROR(AVERAGE(W6:W15),0) -> 5.5 | X17: =IFERROR(AVERAGE(X6:X15),0) -> 5.5 | Z17: MÉDIO DO CARGO | AC17: =IFERROR(AVERAGE(AC6:AC15),0) -> 5.5 | AD17: =IFERROR(AVERAGE(AD6:AD15),0) -> 5.5

Sheet 5.
B2: < HOME | D2: 5. PLANO DE AÇÃO ESPECÍFICO
B4: INDICADOR | D4: CAUSA 1 | F4: CAUSA 2 | H4: CAUSA 3 | J4: CAUSA 4 | L4: CAUSA 5 | N4: AÇÃO PROPOSTA | O4: QUEM | P4: STATUS | Q4: PRAZO
P5: EM ANDAMENTO
P6: ATRASADA
P7: CONCLUÍDA
P8: A INICIAR
P9: EM ANDAMENTO
P10: ATRASADA
P11: CONCLUÍDA
P12: A INICIAR
P13: EM ANDAMENTO

Sheet 1
B2: << VOLTAR À MATRIZ | C2: ='3.'!C6 -> 0
B3: 1
B4: 2
B5: =B4+1 -> 3
B6: =B5+1 -> 4
B7: =B6+1 -> 5
B8: =B7+1 -> 6
B9: =B8+1 -> 7
B10: =B9+1 -> 8
B11: =B10+1 -> 9
B12: =B11+1 -> 10
B13: =B12+1 -> 11
B14: =B13+1 -> 12
B15: =B14+1 -> 13
B16: =B15+1 -> 14
... B32: =B31+1 -> 30
B33: FIM

Sheet 2
B2: << VOLTAR À MATRIZ | C2: ='3.'!C7 -> 0
B3: 1
B4: 2
B5: =B4+1 -> 3
B6: =B5+1 -> 4
B7: =B6+1 -> 5
B8: =B7+1 -> 6
B9: =B8+1 -> 7
B10: =B9+1 -> 8
B11: =B10+1 -> 9
B12: =B11+1 -> 10
B13: =B12+1 -> 11
B14: =B13+1 -> 12
B15: =B14+1 -> 13
B16: =B15+1 -> 14
... B32: =B31+1 -> 30
B33: FIM

Sheet 3
B2: << VOLTAR À MATRIZ | C2: ='3.'!C8 -> 0
B3: 1
B4: 2
B5: =B4+1 -> 3
B6: =B5+1 -> 4
B7: =B6+1 -> 5
B8: =B7+1 -> 6
B9: =B8+1 -> 7
B10: =B9+1 -> 8
B11: =B10+1 -> 9
B12: =B11+1 -> 10
B13: =B12+1 -> 11
B14: =B13+1 -> 12
B15: =B14+1 -> 13
B16: =B15+1 -> 14
... B32: =B31+1 -> 30
B33: FIM

Sheet 4
B2: << VOLTAR À MATRIZ | C2: ='3.'!C9 -> 0
B3: 1
B4: =B3+1 -> 2
B5: =B4+1 -> 3
B6: =B5+1 -> 4
B7: =B6+1 -> 5
B8: =B7+1 -> 6
B9: =B8+1 -> 7
B10: =B9+1 -> 8
B11: =B10+1 -> 9
B12: =B11+1 -> 10
B13: =B12+1 -> 11
B14: =B13+1 -> 12
B15: =B14+1 -> 13
... B32: =B31+1 -> 30
B33: FIM

Sheet 5
B2: << VOLTAR À MATRIZ | C2: ='3.'!C10 -> 0
B3: 1
B4: =B3+1 -> 2
B5: =B4+1 -> 3
B6: =B5+1 -> 4
B7: =B6+1 -> 5
B8: =B7+1 -> 6
B9: =B8+1 -> 7
B10: =B9+1 -> 8
B11: =B10+1 -> 9
B12: =B11+1 -> 10
B13: =B12+1 -> 11
B14: =B13+1 -> 12
B15: =B14+1 -> 13
... B34: =B33+1 -> 32
B35: FIM

Sheet 6
B2: << VOLTAR À MATRIZ | C2: ='3.'!C11 -> 0
B3: 1
B4: 2
B5: =B4+1 -> 3
B6: =B5+1 -> 4
B7: =B6+1 -> 5
B8: 5
B9: 6
B10: 7
B11: 8
B12: 9
B13: 10
B14: 11
B15: 12
B16: 13
B17: 14
B18: 15
B19: 16
... B33: 30
B34: FIM

Sheet 7
B2: << VOLTAR À MATRIZ | C2: ='3.'!C12 -> 0
B3: 1
B4: 2
B5: =B4+1 -> 3
B6: =B5+1 -> 4
B7: =B6+1 -> 5
B8: 5
B9: 6
B10: 7
B11: 8
B12: 9
B13: 10
B14: 11
B15: 12
B16: 13
B17: 14
B18: 15
B19: 16
... B33: 30
B34: FIM

Sheet 8
B2: << VOLTAR À MATRIZ | C2: ='3.'!C13 -> 0
B3: 1
B4: =B3+1 -> 2
B5: =B4+1 -> 3
B6: =B5+1 -> 4
B7: =B6+1 -> 5
B8: =B7+1 -> 6
B9: =B8+1 -> 7
B10: =B9+1 -> 8
B11: =B10+1 -> 9
B12: =B11+1 -> 10
B13: =B12+1 -> 11
B14: =B13+1 -> 12
B15: =B14+1 -> 13
... B32: =B31+1 -> 30
B33: FIM

Sheet 9
B2: << VOLTAR À MATRIZ | C2: ='3.'!C14 -> 0
B3: 1
B4: =B3+1 -> 2
B5: =B4+1 -> 3
B6: =B5+1 -> 4
B7: =B6+1 -> 5
B8: =B7+1 -> 6
B9: =B8+1 -> 7
B10: =B9+1 -> 8
B11: =B10+1 -> 9
B12: =B11+1 -> 10
B13: =B12+1 -> 11
B14: =B13+1 -> 12
B15: =B14+1 -> 13
... B32: =B31+1 -> 30
B33: FIM

Sheet 10
B2: << VOLTAR À MATRIZ | C2: ='3.'!C15 -> 0
B3: 1
B4: =B3+1 -> 2
B5: =B4+1 -> 3
B6: =B5+1 -> 4
B7: =B6+1 -> 5
B8: =B7+1 -> 6
B9: =B8+1 -> 7
B10: =B9+1 -> 8
B11: =B10+1 -> 9
B12: =B11+1 -> 10
B13: =B12+1 -> 11
B14: =B13+1 -> 12
B15: =B14+1 -> 13
... B32: =B31+1 -> 30
B33: FIM

Sheet 11
B2: << VOLTAR À MATRIZ | C2: ='3.'!C15 -> 0
B3: 1
B4: =B3+1 -> 2
B5: =B4+1 -> 3
B6: =B5+1 -> 4
B7: =B6+1 -> 5
B8: =B7+1 -> 6
B9: =B8+1 -> 7
B10: =B9+1 -> 8
B11: =B10+1 -> 9
B12: =B11+1 -> 10
B13: =B12+1 -> 11
B14: =B13+1 -> 12
B15: =B14+1 -> 13
... B32: =B31+1 -> 30
B33: FIM

Sheet 12
B2: << VOLTAR À MATRIZ | C2: ='3.'!C15 -> 0
B3: 1
B4: =B3+1 -> 2
B5: =B4+1 -> 3
B6: =B5+1 -> 4
B7: =B6+1 -> 5
B8: =B7+1 -> 6
B9: =B8+1 -> 7
B10: =B9+1 -> 8
B11: =B10+1 -> 9
B12: =B11+1 -> 10
B13: =B12+1 -> 11
B14: =B13+1 -> 12
B15: =B14+1 -> 13
... B32: =B31+1 -> 30
B33: FIM

Sheet 13
B2: << VOLTAR À MATRIZ | C2: ='3.'!C15 -> 0
B3: 1
B4: =B3+1 -> 2
B5: =B4+1 -> 3
B6: =B5+1 -> 4
B7: =B6+1 -> 5
B8: =B7+1 -> 6
B9: =B8+1 -> 7
B10: =B9+1 -> 8
B11: =B10+1 -> 9
B12: =B11+1 -> 10
B13: =B12+1 -> 11
B14: =B13+1 -> 12
B15: =B14+1 -> 13
... B32: =B31+1 -> 30
B33: FIM

Sheet 14
B2: << VOLTAR À MATRIZ | C2: ='3.'!C15 -> 0
B3: 1
B4: =B3+1 -> 2
B5: =B4+1 -> 3
B6: =B5+1 -> 4
B7: =B6+1 -> 5
B8: =B7+1 -> 6
B9: =B8+1 -> 7
B10: =B9+1 -> 8
B11: =B10+1 -> 9
B12: =B11+1 -> 10
B13: =B12+1 -> 11
B14: =B13+1 -> 12
B15: =B14+1 -> 13
... B32: =B31+1 -> 30
B33: FIM

Sheet 15
B2: << VOLTAR À MATRIZ | C2: ='3.'!C15 -> 0
B3: 1
B4: =B3+1 -> 2
B5: =B4+1 -> 3
B6: =B5+1 -> 4
B7: =B6+1 -> 5
B8: =B7+1 -> 6
B9: =B8+1 -> 7
B10: =B9+1 -> 8
B11: =B10+1 -> 9
B12: =B11+1 -> 10
B13: =B12+1 -> 11
B14: =B13+1 -> 12
B15: =B14+1 -> 13
... B32: =B31+1 -> 30
B33: FIM

Sheet 16
B2: << VOLTAR À MATRIZ | C2: ='3.'!C15 -> 0
B3: 1
B4: =B3+1 -> 2
B5: =B4+1 -> 3
B6: =B5+1 -> 4
B7: =B6+1 -> 5
B8: =B7+1 -> 6
B9: =B8+1 -> 7
B10: =B9+1 -> 8
B11: =B10+1 -> 9
B12: =B11+1 -> 10
B13: =B12+1 -> 11
B14: =B13+1 -> 12
B15: =B14+1 -> 13
... B32: =B31+1 -> 30
B33: FIM

Sheet 17
B2: << VOLTAR À MATRIZ | C2: ='3.'!C15 -> 0
B3: 1
B4: =B3+1 -> 2
B5: =B4+1 -> 3
B6: =B5+1 -> 4
B7: =B6+1 -> 5
B8: =B7+1 -> 6
B9: =B8+1 -> 7
B10: =B9+1 -> 8
B11: =B10+1 -> 9
B12: =B11+1 -> 10
B13: =B12+1 -> 11
B14: =B13+1 -> 12
B15: =B14+1 -> 13
... B32: =B31+1 -> 30
B33: FIM

Sheet 18
B2: << VOLTAR À MATRIZ | C2: ='3.'!C15 -> 0
B3: 1
B4: =B3+1 -> 2
B5: =B4+1 -> 3
B6: =B5+1 -> 4
B7: =B6+1 -> 5
B8: =B7+1 -> 6
B9: =B8+1 -> 7
B10: =B9+1 -> 8
B11: =B10+1 -> 9
B12: =B11+1 -> 10
B13: =B12+1 -> 11
B14: =B13+1 -> 12
B15: =B14+1 -> 13
... B32: =B31+1 -> 30
B33: FIM

Sheet 19
B2: << VOLTAR À MATRIZ | C2: ='3.'!C15 -> 0
B3: 1
B4: =B3+1 -> 2
B5: =B4+1 -> 3
B6: =B5+1 -> 4
B7: =B6+1 -> 5
B8: =B7+1 -> 6
B9: =B8+1 -> 7
B10: =B9+1 -> 8
B11: =B10+1 -> 9
B12: =B11+1 -> 10
B13: =B12+1 -> 11
B14: =B13+1 -> 12
B15: =B14+1 -> 13
... B32: =B31+1 -> 30
B33: FIM

Sheet 20
B2: << VOLTAR À MATRIZ | C2: ='3.'!C15 -> 0
B3: 1
B4: =B3+1 -> 2
B5: =B4+1 -> 3
B6: =B5+1 -> 4
B7: =B6+1 -> 5
B8: =B7+1 -> 6
B9: =B8+1 -> 7
B10: =B9+1 -> 8
B11: =B10+1 -> 9
B12: =B11+1 -> 10
B13: =B12+1 -> 11
B14: =B13+1 -> 12
B15: =B14+1 -> 13
... B32: =B31+1 -> 30
B33: FIM
