Workbook
Name hr_ini: #REF!
Name hr_ini: #REF!
Name hr_ini: #REF!
Name hr_ini: #REF!
Name hr_ini: #REF!
Name hr_ini: #REF!
Name hr_ini: #REF!
Name hr_ini: #REF!
Name hr_ini: #REF!
Name hr_ini: #REF!
Name hr_ini: #REF!
Name hr_ini: #REF!
Name hr_ini: #REF!
Name hr_ini: #REF!
Name hr_ini: #REF!
Name hr_limite: #REF!
Name hr_limite: #REF!
Name hr_limite: #REF!
Name hr_limite: #REF!
Name hr_limite: #REF!
Name hr_limite: #REF!
Name hr_limite: #REF!
Name hr_limite: #REF!
Name hr_limite: #REF!
Name hr_limite: #REF!
Name hr_limite: #REF!
Name hr_limite: #REF!
Name hr_limite: #REF!
Name hr_limite: #REF!
Name hr_limite: #REF!
Name lista_causa: [5]!causa_raiz[Causa Raiz]
Name lista_causa: [5]!causa_raiz[Causa Raiz]
Name lista_causa: [5]!causa_raiz[Causa Raiz]
Name lista_causa: [5]!causa_raiz[Causa Raiz]
Name lista_causa: [5]!causa_raiz[Causa Raiz]
Name lista_causa: [5]!causa_raiz[Causa Raiz]
Name lista_causa: [5]!causa_raiz[Causa Raiz]
Name lista_causa: [5]!causa_raiz[Causa Raiz]
Name lista_causa: #REF!
Name lista_causa: [5]!causa_raiz[Causa Raiz]
Name lista_causa: [5]!causa_raiz[Causa Raiz]
Name lista_causa: [5]!causa_raiz[Causa Raiz]
Name lista_causa: #REF!
Name lista_causa: [5]!causa_raiz[Causa Raiz]
Name lista_causa: [5]!causa_raiz[Causa Raiz]
Name lista_causa: [5]!causa_raiz[Causa Raiz]
Name lista_causa: [5]!causa_raiz[Causa Raiz]
Name lista_causa: #REF!
Name lista_causa: #REF!
Name lista_causa: #REF!
Name lista_causa: #REF!
Name logo: #REF!
Name logo: #REF!
Name logo: #REF!
Name logo: #REF!
Name logo: #REF!
Name logo: #REF!
Name logo: #REF!
Name logo: #REF!
Name logo: #REF!

Sheet TEMPOS
B2: DURAÇÃO DAS AULAS | R2: =D4+H4+L4+P4+T4+X4 -> 0.16538194
B4: 0. COMECE POR AQUI | D4: =D6+D8+D10+D12+D14+D16+D18 -> 0.020196759 | F4: 1. ESTRATÉGICO | H4: =H6+H8+H10+H12+H14+H16+H18 -> 0.041851852 | J4: 2. MARKETING | L4: =L6+L8+L10+L12+L14+L16+L18 -> 0.020659722 | N4: 3. VENDAS | P4: =P6+P8+P10+P12+P14+P16+P18 -> 0.029097222 | R4: 4. PESSOAS | T4: =T6+T8+T10+T12+T14+T16+T18 -> 0.032291667 | V4: 5. FINANCEIRO | X4: =X6+X8+X10+X12+X14+X16+X18+X24 -> 0.021284722
B6: MAPA DA METODOLOGIA | F6: MISSÃO, VISÃO E VALORES | H6: 0.0049768519 | J6: RAIO-X DO CLIENTE DOS SONHOS | L6: 0.0030555556 | N6: AMPULHETA DE VENDAS | P6: 0.0066203704 | R6: RECRUTAMENTO E SELEÇÃO | T6: 0.007025463 | V6: GESTÃO MATRICIAL DE DESPESAS | X6: 0.0074884259
B8: AULA INAUGURAL | D8: 0.0054861111 | F8: MAPA DE CARGOS E FUNÇÕES | H8: 0.0044675926 | J8: CRIAÇÃO DE CONTEÚDOS VIRAIS | L8: 0.0075578704 | N8: GESTÃO DA BASE DE CLIENTES | P8: 0.0034953704 | R8: TREINAMENTO COM FLUXOGRAMA | T8: 0.0051967593 | V8: GESTÃO MATRICIAL DE RECEITAS | X8: 0.0083217593
B10: TESTE DE NIVELAMENTO + EVOLUÇÃO POR PILAR + PPE | D10: 0.0076157407 | F10: REGULAMENTO INTERNO | H10: 0.0036921296 | J10: SOCIAL SELLER | L10: 0.010046296 | N10: SCRIPT DE ATENDIMENTO IDEAL | P10: 0.0034606481 | R10: PRODUTIVIDADE X OCIOSIDADE | T10: 0.0035648148 | V10: GESTÃO DO FLUXO DE CAIXA | X10: 0.005474537
B12: CONTROLE DE METAS + FOTOGRAFIA DA EMPRESA | D12: 0.0070949074 | F12: DESDOBRAMENTO DE METAS | H12: 0.0071875 | N12: QUEBRA DE OBJEÇÕES | P12: 0.0058912037 | R12: FEEDBACKS 1 X 1 COM SEU TIME | T12: 0.0054050926
F14: REUNIÃO NOTA 10 (DIÁRIA) | H14: 0.0032986111 | N14: GATILHOS MENTAIS | P14: 0.0096296296 | R14: TREINAMENTO DAS LIDERANÇAS | T14: 0.0048958333
F16: ANÁLISE DE RESULTADOS DO MÊS | H16: 0.010694444 | R16: PESQUISA DE CLIMA NA EMPRESA | T16: 0.0030439815
F18: CRIAÇÃO DE CULTURA FORTE | H18: 0.0075347222 | R18: ENTREVISTA DE DESLIGAMENTO | T18: 0.0031597222
B20: EXPERTS CONVIDADOS | R20: =D22+H22+L22+P22+T22+X22 -> 0.10606481
F22: 1. ESTRATÉGICO | H22: =H24+H26+H28+H30+H32+H34+H36 -> 0.033275463 | J22: 2. MARKETING | L22: =L24+L26+L28+L30+L32+L34+L36 -> 0.020127315 | N22: 3. VENDAS | P22: =P24+P26+P28+P30+P32+P34+P36 -> 0.052662037 | R22: 4. PESSOAS | T22: =T24+T26+T28+T30+T32+T34+T36+T43 -> 0 | V22: 5. FINANCEIRO | X22: =X24+X26+X28+X30+X32+X34+X36+X43 -> 0
F24: REMUNERAÇÃO VARIÁVEL (TIAGO GUEDES) | H24: 0.033275463 | J24: LIVES SHOP (JULIANA TURMINA) | L24: 0.020127315 | N24: AUTOMAÇÃO E IA PRA VENDAS (ERIC LUCIANO) | P24: 0.052662037 | R24: COMO CRIAR UMA EQUIPE EXCEPCIONAL (2 NO VAREJO)

Sheet PAINEL
A1: SCRIPT DE ATENDIMENTO
B2: DASHBOARD DA MENTORIA | R2: > CLIQUE NAS CÉLULAS PARA ACESSAR O CONTEÚDO < | AB2: LEGENDA
AB3: ✓
B4: 0. COMECE POR AQUI | D4: STATUS | F4: 1. ESTRATÉGICO | H4: STATUS | J4: 2. MARKETING | L4: STATUS | N4: 3. VENDAS | P4: STATUS | R4: 4. PESSOAS | T4: STATUS | V4: 5. FINANCEIRO | X4: STATUS | AB4: X
B6: TESTE DE NIVELAMENTO | D6: ✓ | F6: MISSÃO, VISÃO E VALORES | H6: X | J6: RAIO-X DO CLIENTE DOS SONHOS | L6: X | N6: AMPULHETA DE VENDAS | P6: X | R6: RECRUTAMENTO E SELEÇÃO | T6: X | V6: GESTÃO MATRICIAL DE DESPESAS | X6: X
B8: EVOLUÇÃO POR PILAR | D8: ✓ | F8: MAPA DE CARGOS E FUNÇÕES | H8: X | J8: CRIAÇÃO DE CONTEÚDOS VIRAIS | L8: X | N8: GESTÃO DA BASE DE CLIENTES | P8: X | R8: TREINAMENTO COM FLUXOGRAMA | T8: X | V8: GESTÃO MATRICIAL DE RECEITAS | X8: X
B10: PPE (PLANO DE PRIORIDADES DA EMPRESA) | D10: ✓ | F10: REGULAMENTO INTERNO | H10: X | J10: SOCIAL SELLER | L10: X | N10: SCRIPT DE ATENDIMENTO IDEAL | P10: X | R10: PRODUTIVIDADE X OCIOSIDADE | T10: X | V10: GESTÃO DO FLUXO DE CAIXA | X10: X
B12: CONTROLE DE METAS | D12: X | F12: DESDOBRAMENTO DE METAS | H12: X | J12: LIVES SHOP | L12: X | N12: QUEBRA DE OBJEÇÕES | P12: X | R12: FEEDBACKS 1 X 1 COM SEU TIME | T12: X
B14: FOTOGRAFIA DA EMPRESA | D14: ✓ | F14: REUNIÃO NOTA 10 (DIÁRIA) | H14: X | N14: GATILHOS MENTAIS | P14: X | R14: TREINAMENTO DAS LIDERANÇAS | T14: X
F16: ANÁLISE DE RESULTADOS DO MÊS | H16: X | R16: PESQUISA DE CLIMA NA EMPRESA | T16: X
F18: CRIAÇÃO DE CULTURA FORTE | H18: X | R18: ENTREVISTA DE DESLIGAMENTO | T18: X
F20: REMUNERAÇÃO VARIÁVEL | H20: X

Sheet 0.1
B2: < CLIQUE AQUI E VOLTE AO PAINEL INICIAL | C2: CADEIA DE VALOR
B4: PILAR ESTRATÉGICO | F4: PILAR DE MARKETING | J4: PILAR VENDAS | N4: PILAR DE PESSOAS | R4: PILAR FINANCEIRO | W4: SOCIAL MEDIA | AA4: CAPTAÇÃO DE CONTEÚDOS/EDIÇÃO DE VÍDEOS | AE4: TRÁFEGO PAGO | AI4: SUCESSO DO CLIENTE (CS) | AM4: DESIGN
B6: NATASHA E BRUNO | F6: NATASHA E BRUNO | J6: NATASHA E BRUNO | N6: NATASHA E BRUNO | R6: NATASHA E BRUNO | W6: NATASHA E BRUNO | AA6: NATASHA E BRUNO | AE6: BRUNO | AI6: NATASHA E BRUNO | AM6: NATASHA
B8: ROTINAS DO PILAR | C8: NÍVEL CRÍTICO | D8: NOTA ATUAL | F8: ROTINAS DO PILAR | G8: NÍVEL CRÍTICO | H8: NOTA ATUAL | J8: ROTINAS DO PILAR | K8: NÍVEL CRÍTICO | L8: NOTA ATUAL | N8: ROTINAS DO PILAR | O8: NÍVEL CRÍTICO | P8: NOTA ATUAL | R8: ROTINAS DO PILAR | S8: NÍVEL CRÍTICO | T8: NOTA ATUAL | W8: ROTINAS DO PILAR | X8: NÍVEL CRÍTICO | Y8: NOTA ATUAL | AA8: ROTINAS DO PILAR | AB8: NÍVEL CRÍTICO | AC8: NOTA ATUAL | AE8: ROTINAS DO PILAR | AF8: NÍVEL CRÍTICO | AG8: NOTA ATUAL | AI8: ROTINAS DO PILAR | AJ8: NÍVEL CRÍTICO | AK8: NOTA ATUAL | AM8: ROTINAS DO PILAR | AN8: NÍVEL CRÍTICO | AO8: NOTA ATUAL
B10: DEFINIÇÃO E ALINHAMENTO COM O TIME DE MISSÃO, VISÃO E VALORES (DO CEO ATÉ A OPERAÇÃO) | C10: ALTO | D10: 0 | F10: RAIO-X DO CLIENTE DOS SONHOS, ANÁLISE DA CONCORRÊNCIA E ESTUDO DE MERCADO | G10: ALTO | H10: 0 | J10: EXECUÇÃO DIÁRIA DA AMPULHETA DE VENDAS (DA PROSPECÇÃO ATÉ A VENDA E INDICAÇÕES) | K10: ALTO | L10: 2 | N10: ROTINAS DE RECRUTAMENTO E SELEÇÃO DE NOVOS COLABORADORES | O10: ALTO | P10: 3 | R10: ROTINAS DE CONTAS A PAGAR (GESTÃO DE MULTAS E JUROS EM DIA) | S10: ALTO | T10: 10 | W10: ROTINA DE REUNIÃO DE BRIEFING E DEFINIÇÃO DAS ESTRATÉGICAS DO CLIENTE | X10: ALTO | Y10: 8 | AA10: ROTINA DE REUNIÃO DE BRIEFING E DEFINIÇÃO DAS ESTRATÉGICAS COM O TIME DE SOCIAL MEDIA | AB10: ALTO | AC10: 10 | AE10: ROTINA DE REUNIÃO DE BRIEFING E DEFINIÇÃO DAS ESTRATÉGICAS DO CLIENTE | AF10: ALTO | AG10: 7 | AI10: ROTINA DE REUNIÕES DE BOAS-VINDAS E ALINHAMENTO COM O CLIENTE | AJ10: ALTO | AK10: 8 | AM10: ROTINA DE REUNIÃO DE BRIEFING E DEFINIÇÃO DAS ESTRATÉGICAS COM O SOCIAL MEDIA, TRÁFEGO E CAPTAÇÃO DE CONTEÚDO | AN10: ALTO | AO10: 3
B11: GESTÃO DO ORGANOGRAMA DA EMPRESA E MAPEAMENTO DOS CARGOS E FUNÇÕES | C11: ALTO | D11: 2 | F11: GESTÃO DE PÁGINAS, SITES, GOOGLE MEU NEGÓCIO | G11: ALTO | H11: 0 | J11: GESTÃO CONTÍNUA DA BASE DE CLIENTES (ATIVOS E INATIVOS) | K11: ALTO | L11: 0 | N11: TREINAMENTO INTRODUTÓRIO NA CULTURA E REG. INTERNO PARA NOVOS FUNCIONÁRIOS | O11: ALTO | P11: 2 | R11: ROTINAS DE CONTAS A RECEBER (GESTÃO DA CONSTRUÇÃO DE UM CAIXA FORTE) | S11: ALTO | T11: 5 | W11: ROTINA DE CRIAÇÃO DE PLANEJAMENTO DIÁRIOS, SEMANAIS E MENSAIS DE CONTEÚDO | X11: ALTO | Y11: 8 | AA11: GESTÃO DO CALENDÁRIOS E DE ROTAS DAS VISITAS PARA CAPTAÇÃO DE CONTEÚDO | AB11: ALTO | AC11: 8 | AE11: ROTINA DE DEFINIÇÃO DE METAS DE CAMPANHA (ALCANCE, CLIQUES, LEADS, CONVERSÃO...) | AF11: ALTO | AG11: 5 | AI11: ROTINA DE ATENDIMENTO AO CLIENTE DIÁRIO E SEMANAL (MODO BABÁ) | AJ11: ALTO | AK11: 1 | AM11: GESTÃO DE PRIORIZAÇÃO DAS PRODUÇÕES DE CONTEÚDO (AGENDA DE POSTAGEM) | AN11: ALTO | AO11: 3
B12: ELABORAÇÃO E APRESENTAÇÃO DO REGULAMENTO INTERNO PARA GARANTIR REGRAS E PADRÕES DA EMPRESA | C12: ALTO | D12: 2 | F12: GESTÃO DAS REDES SOCIAIS E CRIAÇÃO DE CONTEÚDOS ORGÂNICOS/VIRAIS | G12: ALTO | H12: 0 | J12: ROTINA/SCRIPT DE ATENDIMENTO AO LEAD/CLIENTE | K12: ALTO | L12: 0 | N12: TREINAMENTO E CAPACITAÇÃO DE COLABORADORES NAS SUAS FUNÇÕES (COM FLUXOGRAMAS) | O12: ALTO | P12: 0 | R12: GESTÃO DO FLUXO DE CAIXA (GESTÃO DA PREVISIBILIDADE DA EMPRESA MÊS A MÊS E PRÓ LABORE DOS SÓCIOS) | S12: ALTO | T12: 2 | W12: ROTINA DE PROGRAMAÇÃO DE POSTAGENS NAS PLATAFORMAS DO CLIENTE | X12: MÉDIO | Y12: 8 | AA12: ROTINA DE VERIFICAÇÃO/CHECKLIST DOS MATERIAIS NECESSÁRIOS PARA A VISITA (MICROFONE, CAMERA, LUZ...) | AB12: MÉDIO | AC12: 8 | AE12: ROTINA DE CRIAÇÃO DA CAMPANHAS, CONJUNTOS DE ANÚNCIOS E CRIATIVOS | AF12: MÉDIO | AG12: 8 | AI12: ROTINA DE COLETA DE FEEDBACKS DOS CLIENTES E COMUNICAÇÃO COM O TIME INTERNO | AJ12: ALTO | AK12: 0 | AM12: ROTINA DE PRODUÇÃO E EDIÇÃO DE CONTEÚDOS (POSTS ESTÁTICOS/ARTES) | AN12: ALTO | AO12: 3
B13: DEFINIÇÃO DE METAS ANUAIS E DESDOBRAMENTO DE METAS MÊS A MÊS | C13: ALTO | D13: 0 | F13: ROTINAS DE SOCIAL SELLER (PROSPECÇÃO ATIVA NAS REDES SOCIAIS) | G13: MÉDIO | H13: 5 | J13: DIAGNÓSTICO DO CLIENTE E MAPEAMENTO DAS NECESSIDADES (AMPULHETA DE VENDAS) | K13: ALTO | L13: 1 | N13: AVALIAÇÃO DE DESEMPENHO DOS FUNCIONÁRIOS | O13: ALTO | P13: 2 | R13: FECHAMENTO MENSAL DOS RESULTADOS E ANÁLISE DA DRE DA EMPRESA | S13: ALTO | T13: 0 | W13: ROTINA DE ROTEIRIZAÇÃO E PRODUÇÃO DE LEGENDAS E COPYS | X13: MÉDIO | Y13: 10 | AA13: ROTINA DA REALIZAÇÃO DA VISITA NAS EMPRESAS (ATENDIMENTO E EXPLICAÇÃO DO SERVIÇO PARA O CLIENTE) | AB13: ALTO | AC13: 10 | AE13: ROTINA DE MONITORAMENTO DE DESEMPENHO DA CAMPANHAS E ANÚNCIOS | AF13: ALTO | AG13: 5 | AI13: GESTÃO DE RISCOS DOS CLIENTES (RECLAMAÇÕES E QUEDA DE ENGAJAMENTO) | AJ13: ALTO | AK13: 0 | AM13: ROTINA DE REVISÃO DOS MATERIAIS PRODUZIDOS (CHECKLIST ANTES DO ENVIO PARA CS) | AN13: MÉDIO | AO13: 3
B14: ROTINA DE REUNIÃO MENSAL: PARA ANÁLISE DOS RESULTADOS (POR ÁREA E INDICADOR) | C14: ALTO | D14: 0 | F14: GESTÃO DE TRÁFEGO PAGO/ANÚNCIOS ONLINE | G14: ALTO | H14: 0 | J14: ROTINA DE COLETA E DIVULGAÇÃO DE PROVAS SOCIAIS | K14: ALTO | L14: 0 | N14: ROTINA DE FEEDBACKS COM FUNCIONÁRIOS (1 A 1) LÍDERES E LIDERADOS | O14: ALTO | P14: 0 | R14: ROTINAS DE PRECIFICAÇÃO E ANÁLISE DAS MARGENS DE LUCRO | S14: ALTO | T14: 3 | W14: ROTINA DE REVISÃO E APROVAÇÃO DE CONTEÚDOS (TEXTO, ESTÉTICA, COERÊNCIA...) | X14: ALTO | Y14: 8 | AA14: ROTINA DE CAPTAÇÃO DAS IMAGENS | AB14: ALTO | AC14: 8 | AE14: ROTINA DE PRODUÇÃO DE RELATÓRIOS SEMANAIS E QUINZENAIS COM DADOS DE DESEMPENHO | AF14: ALTO | AG14: 1 | AI14: GESTÃO DE CALENDÁRIO/AGENDA/ROTA INTERNA DA EQUIPE E CEOs | AJ14: ALTO | AK14: 5 | AM14: ROTINA DE ORGANIZAÇÃO E ATUALIZAÇÃO DE ARQUIVOS E REFERÊNCIAS DAS ARTES (CATÁLOGO) | AN14: MÉDIO | AO14: 0
B15: ROTINA DE REUNIÃO SEMANAL: PARA ALINHAMENTO 1 A 1 (COM LÍDERES DE CADA ÁREA) | C15: ALTO | D15: 0 | F15: PARCERIAS COM EMPRESAS E NEGÓCIOS ESTRATÉGICOS | G15: MÉDIO | H15: 5 | J15: ROTINA DE FOLLOWUP DE PROPOSTAS EM ABERTO PARA CLIENTES | K15: ALTO | L15: 0 | N15: ROTINAS TREINAMENTO E CAPACITAÇÃO DAS LIDERANÇAS DA EMPRESA | O15: MÉDIO | P15: 8 | R15: GESTÃO MATRICIAL DE CUSTOS E DESPESAS (CONTROLE LINHA A LINHA DE TODOS OS GASTOS) | S15: ALTO | T15: 0 | W15: ROTINA DE PRODUÇÃO E EDIÇÃO DE CONTEÚDOS (FOTOS, REELS, STORIES E VÍDEOS) | X15: ALTO | Y15: 8 | AA15: ROTINA DE ENVIO DOS MATERIAIS COLETADOS NA VISITA REALIZADA (DRIVE, TELEGRAM, WHATSAPP, EMAIL...) | AB15: ALTO | AC15: 5 | AE15: ROTINA DE REUNIÃO DE ALINHAMENTO COM O CLIENTE (APRESENTAÇÃO, FEEDBACKS, COLETA DE INFORMAÇÕES...) | AF15: ALTO | AG15: 5 | AI15: ROTINA DE ALINHAMENTO COM TIME INTERNO DA EMPRESA (REUNIÕES, WHATSAPP...) | AJ15: ALTO | AK15: 8
B16: ROTINA DE REUNIÃO DIÁRIA: PARA ALINHAMENTO DO TIME (FOCO NAS ROTINAS E PADRÕES) | C16: ALTO | D16: 0 | F16: GESTÃO DE GRUPO VIP NO WHATSAPP/MENSAGENS VIA LISTA DE TRANSMISSÃO | G16: MÉDIO | H16: NA | J16: ELABORAÇÃO E CONSTRUÇÃO DE ORÇAMENTOS PARA O CLIENTE | K16: MÉDIO | L16: 6 | N16: GESTÃO DA FOLHA DE PAGAMENTO E DA REMUNERAÇÃO VARIÁVEL (SE HOUVER) | O16: MÉDIO | P16: 10 | R16: GESTÃO MATRICIAL DE RECEITAS E VENDAS (CONTROLE DE VOLUME E LUCRO) | S16: ALTO | T16: 5 | W16: GESTÃO DE ANÁLISE DE RESULTADOS (INDICADORES) DOS POSTS PARA PADRONIZAÇÃO DE BOAS PRÁTICAS E AÇÕES CORRETIVAS | X16: ALTO | Y16: 1 | AA16: ROTINA DE EDIÇÃO E PRODUÇÃO DOS MATERIAIS COLETADOS | AB16: ALTO | AC16: 6 | AE16: ROTINA DE ALINHAMENTO COM TIME INTERNO DA EMPRESA (REUNIÕES, WHATSAPP...) | AF16: ALTO | AG16: 5 | AI16: ROTINA DE ENVIO DE MATERIAIS PARA APROVAÇÃO DO CLIENTE (RECEBIDO PELO TIME INTERNO) | AJ16: ALTO | AK16: 5
B17: ROTINA DE TREINAMENTO E FORMAÇÃO DE NOVAS LIDERANÇAS PARA AS POSIÇÕES CRÍTICAS | C17: MÉDIO | D17: 5 | F17: ROTINA DE LIVES SHOP PARA DIVULGAÇÃO DE PRODUTOS/OFERTAS ESPECIAIS | G17: MÉDIO | H17: NA | J17: ROTINA DE QUEBRA DE OBJEÇÕES E USO DE GATILHOS MENTAIS | K17: MÉDIO | L17: 7 | N17: AÇÕES DE PREMIAÇÃO, BONIFICAÇÃO E DE PROMOÇÃO DA MERITOCRACIA | O17: MÉDIO | P17: 0 | R17: ROTINA DE EMISSÃO DE NOTAS FISCAIS | S17: MÉDIO | T17: 10 | W17: ROTINA DE REUNIÃO DE ALINHAMENTO COM O CLIENTE (APRESENTAÇÃO, FEEDBACKS, COLETA DE INFORMAÇÕES...) | X17: ALTO | Y17: 5 | AI17: ROTINA DE ATUALIZAÇÃO E GESTÃO DO CATÁLOGO DE TRABALHOS REALIZADOS (DRIVE DOS CLIENTES) | AJ17: MÉDIO | AK17: 0
B18: AÇÕES DE DESENVOLVIMENTO E FORTALECIMANTO DA CULTURA ORGANIZACIONAL | C18: BAIXO | D18: 0 | F18: PARCERIAS COM INFLUENCERS E PROFISSIONAIS DO NICHO | G18: BAIXO | H18: 0 | J18: ROTINA DE UPSELL, DOWNSELL, CROSSELL E COMBOS NAS NEGOCIAÇÕES | K18: MÉDIO | L18: 5 | N18: PESQUISA DE CLIMA ORGANIZACIONAL PARA PADRONIZAÇÃO DE BOAS PRÁTICAS E AÇÕES CORRETIVAS | O18: MÉDIO | P18: 0 | R18: GESTÃO DE INADIMPLENTES | S18: MÉDIO | T18: 10 | W18: ROTINA DE ALINHAMENTO COM TIME INTERNO DA EMPRESA (REUNIÕES, WHATSAPP...) | X18: ALTO | Y18: 1
B19: ROTINA DE ANÁLISE DE CONCORRENTES E TENDÊNCIAS DE MERCADO PARA O SETOR (RISCOS E OPORTUNIDADES) | C19: BAIXO | D19: 0 | F19: ELABORAÇÃO DE MATERIAIS, FOLDERS, PANFLETOS INSTITUCIONAIS, CARTAZES, ETC | G19: BAIXO | H19: 0 | J19: GESTÃO DE FERRAMENTAS DE AUTOMAÇÃO E I.A. (INTELIGÊNCIA ARTIFICIAL) | K19: BAIXO | L19: 5 | N19: ROTINAS DE PROCESSO DEMISSIONAL E ENTREVISTA DE DESLIGAMENTO (SE APLICÁVEL) | O19: BAIXO | P19: 0 | R19: GESTÃO DO FUNDO DE RESERVA E PRÓ-LABORE DOS SÓCIOS | S19: BAIXO | T19: 0
B21: MÉDIA DO PILAR | D21: =AVERAGE(D10:D19) -> 0.9 | F21: MÉDIA DO PILAR | H21: =AVERAGE(H10:H19) -> 1.25 | J21: MÉDIA DO PILAR | L21: =AVERAGE(L10:L19) -> 2.6 | N21: MÉDIA DO PILAR | P21: =AVERAGE(P10:P19) -> 2.5 | R21: MÉDIA DO PILAR | T21: =AVERAGE(T10:T19) -> 4.5 | W21: MÉDIA DO PILAR | Y21: =AVERAGE(Y10:Y19) -> 6.3333333 | AA21: MÉDIA DO PILAR | AC21: =AVERAGE(AC10:AC19) -> 7.8571429 | AE21: MÉDIA DO PILAR | AG21: =AVERAGE(AG10:AG19) -> 5.1428571 | AI21: MÉDIA DO PILAR | AK21: =AVERAGE(AK10:AK19) -> 3.375 | AM21: MÉDIA DO PILAR | AO21: =AVERAGE(AO10:AO19) -> 2.4

Sheet 0.2
B2: < CLIQUE AQUI E VOLTE AO PAINEL INICIAL | C2: AVALIAÇÃO DOS PILARES EMPRESARIAIS (EVOLUÇÃO TRIMESTRAL)
B4: PILARES DO TESTE DE NIVELAMENTO EMPRESARIAL | C4: Coluna preenchida de forma automática | D4: Preencher a data do onboarding e colcar valores nas datas | E4: AVALIAÇÃO 1 (90 dias após o onboarding) | F4: AVALIAÇÃO 2 (180 dias após a Avaliação 1) | G4: AVALIAÇÃO 3 (270 dias após a Avaliação 2)
C5: =TODAY() -> 45951 | D5: 45938 | E5: =D5+90 -> 46028 | F5: =E5+90 -> 46118 | G5: =F5+90 -> 46208
B6: ESTRATÉGICO | C6: ='0.1'!D21 -> 0.9 | D6: =C6 -> 0.9
B7: MARKETING | C7: ='0.1'!H21 -> 1.25 | D7: =C7 -> 1.25
B8: VENDAS | C8: ='0.1'!L21 -> 2.6 | D8: =C8 -> 2.6
B9: PESSOAS | C9: ='0.1'!P21 -> 2.5 | D9: =C9 -> 2.5
B10: FINANCEIRO | C10: ='0.1'!T21 -> 4.5 | D10: =C10 -> 4.5
B11: SOCIAL MEDIA | C11: ='0.1'!Y21 -> 6.3333333 | D11: 6.3
B12: CAPTAÇÃO DE CONTEÚDOS | C12: ='0.1'!AC21 -> 7.8571429 | D12: 7.9
B13: TRÁFEGO PAGO | C13: ='0.1'!AG21 -> 5.1428571 | D13: 5.1
B14: SUCESSO DO CLIENTE | C14: ='0.1'!AK21 -> 3.375 | D14: 3.4
B15: DESIGN | C15: ='0.1'!AO21 -> 2.4 | D15: 2.4
B16: TOTAL | C16: =AVERAGE(C6:C15) -> 3.6858333 | D16: 3.7
D17: =SUM(D6:D16) -> 40.55
B18: LEGENDA DO GRÁFICO | E18: ABAIXO DE 6 | F18: ENTRE 6,1 E 8 | G18: ENTRE 8,1 E 10

Sheet 0.3
D2: < CLIQUE AQUI E VOLTE AO PAINEL INICIAL | E2: PLANO DE PRIORIDADES DA EMPRESA
C4: # | D4: PILAR | E4: ROTINA | F4: NÍVEL CRÍTICO | G4: NOTA ATUAL | H4: AÇÃO CORRETIVA | I4: QUEM | J4: PRAZO | K4: STATUS | M4: LEGENDA
C6: 1 | D6: ESTRATÉGICO | E6: DEFINIÇÃO E ALINHAMENTO COM O TIME DE MISSÃO, VISÃO E VALORES (DO CEO ATÉ A OPERAÇÃO) | F6: ALTO | G6: 0 | H6: 1. ASSISTIR A AULA DE MISSÃO, VISÃO E VALORES PARA DEFINIR ESSES PILARES NA EMPRESA (USAR PLANILHA 1.1) 2. REALIZAR REUNIÃO DE ALINHAMENTO COM O TIME PARA INFORMAR A TODOS ESSES 3 PRINCÍPIOS | I6: BRUNO | J6: 46028 | K6: EM ANDAMENTO | M6: A INICIAR
C7: =C6+1 -> 2 | D7: ESTRATÉGICO | E7: GESTÃO DO ORGANOGRAMA DA EMPRESA E MAPEAMENTO DOS CARGOS E FUNÇÕES | F7: ALTO | G7: 2 | H7: 1. ASSISTIR A AULA DE CARGOS E FUNÇÕES PARA DEFINIR AS EXPECTATIVAS E ATIVIDADE DE CADA CARGO (USAR PLANILHA 1.2) 2. REALIZAR REUNIÃO DE ALINHAMENTO COM O TIME PARA TRAZER CLAREZA A RESPEITO DAS FUNÇÕES DE TODOS OS MEMBROS DA EQUIPE | I7: NATASHA | J7: 46028 | K7: A INICIAR | M7: EM ANDAMENTO
C8: =C7+1 -> 3 | D8: ESTRATÉGICO | E8: ELABORAÇÃO E APRESENTAÇÃO DO REGULAMENTO INTERNO PARA GARANTIR REGRAS E PADRÕES DA EMPRESA | F8: ALTO | G8: 2 | H8: 1. ASSISTIR A AULA DE REGULAMENTO INTERNO PARA CONSTRUIR O DOCUMENTO QUE CONTÉM AS REGRAS E PADRÕES DA EMPRESA (USAR PLANILHA 1.3) 2. REALIZAR REUNIÃO DE ALINHAMENTO COM O TIME PARA VALIDAR O DOCUMENTO DE REGULAMENTO INTERNO COM A EQUIPE | I8: NATASHA | J8: 46028 | K8: A INICIAR | M8: CONCLUÍDA
C9: =C8+1 -> 4 | D9: ESTRATÉGICO | E9: DEFINIÇÃO DE METAS ANUAIS E DESDOBRAMENTO DE METAS MÊS A MÊS | F9: ALTO | G9: 0 | H9: 1. ASSISTIR A AULA DE CONTROLE DE METAS E FOTOGRAFIA DA EMPRESA PARA OTIMIZAR OS CONTROLES DA LIDERANÇA (USAR PLANILHA 0.4) 2. CRIAR ROTINA DA LIDERANÇA DE ANÁLISE DOS DADOS APÓS O FECHAMENTO DO RESULTADO MENSAL | I9: BRUNO | J9: 46028 | K9: A INICIAR | M9: ATRASADA
C10: =C9+1 -> 5 | D10: ESTRATÉGICO | E10: ROTINA DE REUNIÃO MENSAL: PARA ANÁLISE DOS RESULTADOS (POR ÁREA E INDICADOR) | F10: ALTO | G10: 0 | H10: 1. ASSISTIR A AULA DE ANÁLISE DOS RESULTADOS MENSAIS (MÓDULO 1) DA EMPRESA PARA CRIAR ROTINA COM SÓCIOS E LÍDERES 2. CRIAR ROTINA DA LIDERANÇA DE ANÁLISE DOS DADOS APÓS O FECHAMENTO DO RESULTADO MENSAL | I10: BRUNO | J10: 46028 | K10: A INICIAR
C11: =C10+1 -> 6 | D11: ESTRATÉGICO | E11: ROTINA DE REUNIÃO SEMANAL: PARA ALINHAMENTO 1 A 1 (COM LÍDERES DE CADA ÁREA) | F11: ALTO | G11: 0 | K11: A INICIAR
C12: =C11+1 -> 7 | D12: ESTRATÉGICO | E12: ROTINA DE REUNIÃO DIÁRIA: PARA ALINHAMENTO DO TIME (FOCO NAS ROTINAS E PADRÕES) | F12: ALTO | G12: 0 | H12: 1. ASSISTIR A AULA DE REUNIÃO DIÁRIA NOTA 10 PARA OTIMIZAR OS ALINHAMENTO COM A EQUIPE 2. CRIAR ROTINA DE REUNIÕES DIÁRIAS COM O TIME PARA REDUZIR RETRABALHOS E FALHAS DE COMUNICAÇÃO | I12: NATASHA | J12: 46028 | K12: A INICIAR
C13: =C12+1 -> 8 | D13: MARKETING | E13: RAIO-X DO CLIENTE DOS SONHOS, ANÁLISE DA CONCORRÊNCIA E ESTUDO DE MERCADO | F13: ALTO | G13: 0 | K13: A INICIAR
C14: =C13+1 -> 9 | D14: MARKETING | E14: GESTÃO DE PÁGINAS, SITES, GOOGLE MEU NEGÓCIO | F14: ALTO | G14: 0 | K14: A INICIAR
C15: =C14+1 -> 10 | D15: MARKETING | E15: GESTÃO DAS REDES SOCIAIS E CRIAÇÃO DE CONTEÚDOS ORGÂNICOS/VIRAIS | F15: ALTO | G15: 0 | K15: A INICIAR
C16: =C15+1 -> 11 | D16: MARKETING | E16: GESTÃO DE TRÁFEGO PAGO/ANÚNCIOS ONLINE | F16: ALTO | G16: 0 | K16: A INICIAR
C17: =C16+1 -> 12 | D17: VENDAS | E17: EXECUÇÃO DIÁRIA DA AMPULHETA DE VENDAS (DA PROSPECÇÃO ATÉ A VENDA E INDICAÇÕES) | F17: ALTO | G17: 2 | K17: A INICIAR
C18: =C17+1 -> 13 | D18: VENDAS | E18: GESTÃO CONTÍNUA DA BASE DE CLIENTES (ATIVOS E INATIVOS) | F18: ALTO | G18: 0 | K18: A INICIAR
C19: =C18+1 -> 14 | D19: VENDAS | E19: ROTINA/SCRIPT DE ATENDIMENTO AO LEAD/CLIENTE | F19: ALTO | G19: 0 | K19: A INICIAR
C20: =C19+1 -> 15 | D20: VENDAS | E20: DIAGNÓSTICO DO CLIENTE E MAPEAMENTO DAS NECESSIDADES (AMPULHETA DE VENDAS) | F20: ALTO | G20: 1 | K20: A INICIAR
C21: =C20+1 -> 16 | D21: VENDAS | E21: ROTINA DE COLETA E DIVULGAÇÃO DE PROVAS SOCIAIS | F21: ALTO | G21: 0 | K21: A INICIAR
C22: =C21+1 -> 17 | D22: VENDAS | E22: ROTINA DE FOLLOWUP DE PROPOSTAS EM ABERTO PARA CLIENTES | F22: ALTO | G22: 0 | K22: A INICIAR
C23: =C22+1 -> 18 | D23: PESSOAS | E23: ROTINAS DE RECRUTAMENTO E SELEÇÃO DE NOVOS COLABORADORES | F23: ALTO | G23: 3 | K23: A INICIAR
C24: =C23+1 -> 19 | D24: PESSOAS | E24: TREINAMENTO INTRODUTÓRIO NA CULTURA E REG. INTERNO PARA NOVOS FUNCIONÁRIOS | F24: ALTO | G24: 2 | K24: A INICIAR
... C51: =C50+1 -> 46 | D51: DESIGN | E51: ROTINA DE PRODUÇÃO E EDIÇÃO DE CONTEÚDOS (POSTS ESTÁTICOS/ARTES) | F51: ALTO | G51: 3 | K51: A INICIAR

Sheet 0.4
B2: < CLIQUE AQUI E VOLTE AO PAINEL INICIAL | C2: CONTROLE DE METAS (ANÁLISE MENSAL)
B4: Indicador | C4: FATURAMENTO
B5: Responsável | C5: BRUNO
B6: Última atualização | C6: 45951
B7: Sentido do indicador
D8: 1 | E8: =IF(COUNT(E11)<>0,D8+1,D8) -> 2 | F8: =IF(COUNT(F11)<>0,E8+1,E8) -> 3 | G8: =IF(COUNT(G11)<>0,F8+1,F8) -> 4 | H8: =IF(COUNT(H11)<>0,G8+1,G8) -> 4 | I8: =IF(COUNT(I11)<>0,H8+1,H8) -> 4 | J8: =IF(COUNT(J11)<>0,I8+1,I8) -> 4 | K8: =IF(COUNT(K11)<>0,J8+1,J8) -> 4 | L8: =IF(COUNT(L11)<>0,K8+1,K8) -> 4 | ... O8: =IF(COUNT(O11)<>0,N8+1,N8) -> 4 | AG8: =MAX($D8:$O8) -> 4
B9: 2025 | C9: Histórico Anual | D9: 45962 | E9: =DATE(YEAR(D9),MONTH(D9)+1,DAY(D9)) -> 45992 | F9: =DATE(YEAR(E9),MONTH(E9)+1,DAY(E9)) -> 46023 | G9: =DATE(YEAR(F9),MONTH(F9)+1,DAY(F9)) -> 46054 | H9: =DATE(YEAR(G9),MONTH(G9)+1,DAY(G9)) -> 46082 | I9: =DATE(YEAR(H9),MONTH(H9)+1,DAY(H9)) -> 46113 | J9: =DATE(YEAR(I9),MONTH(I9)+1,DAY(I9)) -> 46143 | K9: =DATE(YEAR(J9),MONTH(J9)+1,DAY(J9)) -> 46174 | L9: =DATE(YEAR(K9),MONTH(K9)+1,DAY(K9)) -> 46204 | ... O9: =DATE(YEAR(N9),MONTH(N9)+1,DAY(N9)) -> 46296 | P9: TOTAL | AF9: Mês | AG9: =HLOOKUP(AG$8,$D$8:$P$14,2,0) -> 46054 | AH9: Extra | AI9: Acumulado
B10: Meta | C10: =AVERAGE(D10:O10) -> 22333.333 | D10: 15000 | E10: 18000 | F10: =E10+1000 -> 19000 | G10: =F10+1000 -> 20000 | H10: =G10+1000 -> 21000 | I10: =H10+1000 -> 22000 | J10: =I10+1000 -> 23000 | K10: =J10+1000 -> 24000 | L10: =K10+1000 -> 25000 | M10: =L10+1000 -> 26000 | ... O10: =N10+1000 -> 28000 | P10: =SUM(D10:O10) -> 268000 | AF10: ="Meta "&PROPER(TEXT(AG9,"mmm")) -> Meta Fev | AG10: =HLOOKUP(AG$8,$D$8:$P$14,3,0) -> 20000 | AH10: Meta acum. | AI10: =P10 -> 268000
B11: Realizado | C11: =AVERAGE(D11:O11) -> 18249.75 | D11: 16000 | E11: 17000 | F11: 20000 | G11: 19999 | P11: =SUM(D11:O11) -> 72999 | AF11: ="Real "&PROPER(TEXT(AG9,"mmm")) -> Real Fev | AG11: =HLOOKUP(AG$8,$D$8:$P$14,4,0) -> 19999 | AH11: Real acum. | AI11: =P11 -> 72999
B12: Abaixo da meta | C12: - | D12: =IF(D11<D10,D11,"") | E12: =IF(E11<E10,E11,"") -> 17000 | F12: =IF(F11<F10,F11,"") | G12: =IF(G11<G10,G11,"") -> 19999 | H12: =IF(H11<H10,H11,"") -> 0 | I12: =IF(I11<I10,I11,"") -> 0 | J12: =IF(J11<J10,J11,"") -> 0 | K12: =IF(K11<K10,K11,"") -> 0 | ... O12: =IF(O11<O10,O11,"") -> 0 | AF12: Abaixo da meta | AI12: =P12 -> 0
B13: Acima da meta | AF13: Acima da meta | AI13: =P13 -> 0
B14: Desvio mensal | C14: =C11-C10 -> -4083.5833 | D14: =D11-D10 -> 1000 | E14: =E11-E10 -> -1000 | F14: =F11-F10 -> 1000 | G14: =G11-G10 -> -1 | H14: =H11-H10 -> -21000 | I14: =I11-I10 -> -22000 | J14: =J11-J10 -> -23000 | ... P14: =P11-P10 -> -195001 | AF14: Diferença | AG14: =HLOOKUP(AG$8,$D$8:$P$14,7,0) -> -1 | AI14: =P14 -> -195001
AF16: Vermelho | AG16: =IF(AG14<0,1,0) -> 1
B18: Indicador | C18: LUCRO
B19: Responsável | C19: BRUNO
B20: Última atualização | C20: 45951
B21: Sentido do indicador
D22: 1 | E22: =IF(COUNT(E25)<>0,D22+1,D22) -> 1 | F22: =IF(COUNT(F25)<>0,E22+1,E22) -> 1 | G22: =IF(COUNT(G25)<>0,F22+1,F22) -> 1 | H22: =IF(COUNT(H25)<>0,G22+1,G22) -> 1 | I22: =IF(COUNT(I25)<>0,H22+1,H22) -> 1 | J22: =IF(COUNT(J25)<>0,I22+1,I22) -> 1 | K22: =IF(COUNT(K25)<>0,J22+1,J22) -> 1 | L22: =IF(COUNT(L25)<>0,K22+1,K22) -> 1 | ... O22: =IF(COUNT(O25)<>0,N22+1,N22) -> 1 | AG22: =MAX($D22:$O22) -> 1
B23: 2025 | C23: Histórico Anual | D23: =D9 -> 45962 | E23: =DATE(YEAR(D23),MONTH(D23)+1,DAY(D23)) -> 45992 | F23: =DATE(YEAR(E23),MONTH(E23)+1,DAY(E23)) -> 46023 | G23: =DATE(YEAR(F23),MONTH(F23)+1,DAY(F23)) -> 46054 | H23: =DATE(YEAR(G23),MONTH(G23)+1,DAY(G23)) -> 46082 | I23: =DATE(YEAR(H23),MONTH(H23)+1,DAY(H23)) -> 46113 | J23: =DATE(YEAR(I23),MONTH(I23)+1,DAY(I23)) -> 46143 | K23: =DATE(YEAR(J23),MONTH(J23)+1,DAY(J23)) -> 46174 | L23: =DATE(YEAR(K23),MONTH(K23)+1,DAY(K23)) -> 46204 | ... O23: =DATE(YEAR(N23),MONTH(N23)+1,DAY(N23)) -> 46296 | P23: TOTAL | AF23: Mês | AG23: =HLOOKUP(AG$22,$D$22:$P$28,2,0) -> 45962 | AH23: Extra | AI23: Acumulado
B24: Meta | C24: =AVERAGE(D24:O24) -> 17866.667 | D24: =80%*D10 -> 12000 | E24: =80%*E10 -> 14400 | F24: =80%*F10 -> 15200 | G24: =80%*G10 -> 16000 | H24: =80%*H10 -> 16800 | I24: =80%*I10 -> 17600 | J24: =80%*J10 -> 18400 | K24: =80%*K10 -> 19200 | ... O24: =80%*O10 -> 22400 | P24: =SUM(D24:O24) -> 214400 | AF24: ="Meta "&PROPER(TEXT(AG23,"mmm")) -> Meta Nov | AG24: =HLOOKUP(AG$22,$D$22:$P$28,3,0) -> 12000 | AH24: Meta acum. | AI24: =P24 -> 214400
B25: Realizado | C25: =AVERAGE(D25:O25) -> #DIV/0! | P25: =SUM(D25:O25) -> 0 | AF25: ="Real "&PROPER(TEXT(AG23,"mmm")) -> Real Nov | AG25: =HLOOKUP(AG$22,$D$22:$P$28,4,0) -> 0 | AH25: Real acum. | AI25: =P25 -> 0
B26: Abaixo da meta | C26: - | D26: =IF(D25<D24,D25,"") -> 0 | E26: =IF(E25<E24,E25,"") -> 0 | F26: =IF(F25<F24,F25,"") -> 0 | G26: =IF(G25<G24,G25,"") -> 0 | H26: =IF(H25<H24,H25,"") -> 0 | I26: =IF(I25<I24,I25,"") -> 0 | J26: =IF(J25<J24,J25,"") -> 0 | K26: =IF(K25<K24,K25,"") -> 0 | ... O26: =IF(O25<O24,O25,"") -> 0 | AF26: Abaixo da meta | AI26: =P26 -> 0
B27: Acima da meta | AF27: Acima da meta | AI27: =P27 -> 0
B28: Desvio mensal | C28: =C25-C24 -> #DIV/0! | D28: =D25-D24 -> -12000 | E28: =E25-E24 -> -14400 | F28: =F25-F24 -> -15200 | G28: =G25-G24 -> -16000 | H28: =H25-H24 -> -16800 | I28: =I25-I24 -> -17600 | J28: =J25-J24 -> -18400 | ... P28: =P25-P24 -> -214400 | AF28: Diferença | AG28: =HLOOKUP(AG$22,$D$22:$P$28,7,0) -> -12000 | AI28: =P28 -> -214400
AF30: Vermelho | AG30: =IF(AG28<0,1,0) -> 1
B32: Indicador | C32: DESPESAS
B33: Responsável | C33: BRUNO
B34: Última atualização | C34: 45951
B35: Sentido do indicador
D36: 1 | E36: =IF(COUNT(E39)<>0,D36+1,D36) -> 1 | F36: =IF(COUNT(F39)<>0,E36+1,E36) -> 1 | G36: =IF(COUNT(G39)<>0,F36+1,F36) -> 1 | H36: =IF(COUNT(H39)<>0,G36+1,G36) -> 1 | I36: =IF(COUNT(I39)<>0,H36+1,H36) -> 1 | J36: =IF(COUNT(J39)<>0,I36+1,I36) -> 1 | K36: =IF(COUNT(K39)<>0,J36+1,J36) -> 1 | L36: =IF(COUNT(L39)<>0,K36+1,K36) -> 1 | ... O36: =IF(COUNT(O39)<>0,N36+1,N36) -> 1 | AG36: =MAX($D36:$O36) -> 1
B37: 2025 | C37: Histórico Anual | D37: =D9 -> 45962 | E37: =DATE(YEAR(D37),MONTH(D37)+1,DAY(D37)) -> 45992 | F37: =DATE(YEAR(E37),MONTH(E37)+1,DAY(E37)) -> 46023 | G37: =DATE(YEAR(F37),MONTH(F37)+1,DAY(F37)) -> 46054 | H37: =DATE(YEAR(G37),MONTH(G37)+1,DAY(G37)) -> 46082 | I37: =DATE(YEAR(H37),MONTH(H37)+1,DAY(H37)) -> 46113 | J37: =DATE(YEAR(I37),MONTH(I37)+1,DAY(I37)) -> 46143 | K37: =DATE(YEAR(J37),MONTH(J37)+1,DAY(J37)) -> 46174 | L37: =DATE(YEAR(K37),MONTH(K37)+1,DAY(K37)) -> 46204 | ... O37: =DATE(YEAR(N37),MONTH(N37)+1,DAY(N37)) -> 46296 | P37: TOTAL | AF37: Mês | AG37: =HLOOKUP(AG$36,$D$36:$P$42,2,0) -> 45962 | AH37: Extra | AI37: Acumulado
B38: Meta | C38: =AVERAGE(D38:O38) -> 19250 | D38: 16000 | E38: 16000 | F38: 16000 | G38: 19000 | H38: 19000 | I38: 19000 | J38: 19000 | K38: 19000 | L38: 22000 | M38: 22000 | N38: 22000 | O38: 22000 | P38: =SUM(D38:O38) -> 231000 | AF38: ="Meta "&PROPER(TEXT(AG37,"mmm")) -> Meta Nov | AG38: =HLOOKUP(AG$36,$D$36:$P$42,3,0) -> 16000 | AH38: Meta acum. | AI38: =P38 -> 231000
B39: Realizado | C39: =AVERAGE(D39:O39) -> #DIV/0! | P39: =SUM(D39:O39) -> 0 | AF39: ="Real "&PROPER(TEXT(AG37,"mmm")) -> Real Nov | AG39: =HLOOKUP(AG$36,$D$36:$P$42,4,0) -> 0 | AH39: Real acum. | AI39: =P39 -> 0
B40: Abaixo da meta | C40: - | D40: =IF(D39>D38,D39,"") | E40: =IF(E39>E38,E39,"") | F40: =IF(F39>F38,F39,"") | G40: =IF(G39>G38,G39,"") | H40: =IF(H39>H38,H39,"") | I40: =IF(I39>I38,I39,"") | J40: =IF(J39>J38,J39,"") | K40: =IF(K39>K38,K39,"") | ... O40: =IF(O39>O38,O39,"") | AF40: Abaixo da meta | AI40: =P40 -> 0
B41: Acima da meta | AF41: Acima da meta | AI41: =P41 -> 0
B42: Desvio mensal | C42: =C39-C38 -> #DIV/0! | D42: =D39-D38 -> -16000 | E42: =E39-E38 -> -16000 | F42: =F39-F38 -> -16000 | G42: =G39-G38 -> -19000 | H42: =H39-H38 -> -19000 | I42: =I39-I38 -> -19000 | J42: =J39-J38 -> -19000 | ... P42: =P39-P38 -> -231000 | AF42: Diferença | AG42: =HLOOKUP(AG$36,$D$36:$P$42,7,0) -> -16000 | AI42: =P42 -> -231000
AF44: Verde | AG44: =IF(AG42<=0,1,0) -> 1
AF45: Vermelho | AG45: =IF(AG42>0,1,0) -> 0

Sheet 0.5
D2: < CLIQUE AQUI E VOLTE AO PAINEL INICIAL | E2: FOTOGRAFIA DA EMPRESA (CNPJ X CPF)
C4: # | D4: PERGUNTAS | E4: COMO CALCULAR | F4: MÉDIA HISTÓRICA (ÚLTIMOS 12 MESES) | G4: 47757 | H4: =DATE(YEAR(G4),MONTH(G4)+1,DAY(G4)) -> 47788 | I4: =DATE(YEAR(H4),MONTH(H4)+1,DAY(H4)) -> 47818 | J4: =DATE(YEAR(I4),MONTH(I4)+1,DAY(I4)) -> 47849 | K4: =DATE(YEAR(J4),MONTH(J4)+1,DAY(J4)) -> 47880 | L4: =DATE(YEAR(K4),MONTH(K4)+1,DAY(K4)) -> 47908 | M4: =DATE(YEAR(L4),MONTH(L4)+1,DAY(L4)) -> 47939 | N4: =DATE(YEAR(M4),MONTH(M4)+1,DAY(M4)) -> 47969 | O4: =DATE(YEAR(N4),MONTH(N4)+1,DAY(N4)) -> 48000 | ... R4: =DATE(YEAR(Q4),MONTH(Q4)+1,DAY(Q4)) -> 48092
C5: 1 | D5: Qual o seu faturamento médio mensal? | E5: Total de vendas em média nos últimos meses | F5: 15000 | G5: 1000000 | H5: 1000000 | I5: 1000000 | J5: 1000000 | K5: 1000000 | L5: 1000000 | M5: 1000000 | N5: 1000000 | O5: 1000000 | P5: 1000000 | Q5: 1000000 | R5: 1000000
C6: 2 | D6: Qual seu gasto médio mensal? | E6: Total de obrigações que você possui com sua empresa (alugel, salários, etc) | F6: NÃO SABE EXATAMENTE
C7: 3 | D7: Qual seu lucro médio mensal? | E7: Total de dinheiro limpo que tem sobrado ao final de cada mês no seu caixa | F7: NÃO SABE EXATAMENTE
C8: 4 | D8: Qual seu fundo de reserva hoje? | E8: Total de dinheiro separado para eventuais emergências da empresa | F8: 37000
C9: 5 | D9: Qual seu pró-labore hoje? | E9: Total (em R$) que você retira da empresa para se pagar (seu salário como dono(a)) | F9: 11000
C10: 6 | D10: Qual o número de funcionários você possui? | E10: Total de pessoas que trabalham com você em sua empresa (contando com você) | F10: 5
C11: 7 | D11: Quantas horas em média você trabalha por dia? | E11: Total de horas que você dedica a sua empresa ao longo de 1 dia de trabalho | F11: 12
C12: 8 | D12: Quantos dias 100% offline você tira ao mês? | E12: Total de dias que você consegue tirar no mês para descansar e se dedicar à família | F12: 4
C13: 9 | D13: De 0 a 10 que nota você dá para a EQUIPE que toca as rotinas da sua empresa? | E13: Avalie criticamente como sua empresa está organizada hoje | F13: 7
C14: 10 | D14: De 0 a 10 que nota você dá para VOCÊ como gestor(a) da sua empresa? | E14: Avalie criticamente como você está preparado(a) hoje | F14: 5

Sheet 1.1
B2: < CLIQUE AQUI E VOLTE AO PAINEL INICIAL | D2: MISSÃO, VISÃO E VALORES
B4: MISSÃO | D4: VISÃO | F4: VALORES | H4: O QUE SIGNIFICA ESSE VALOR?
B6: TRANSFORMAR MARCAS EM EXPERIÊNCIAS VIVAS POR MEIO DA INTEGRAÇÃO ESTRATÉGICA DE PESSOAS, IDEIAS E FERRAMENTAS DIGITAIS, CRIANDO SOLUÇÕES DE MARKETING QUE FUNCIONAM EM HARMONIA COM OS OBJETIVOS DOS CLIENTES | D6: VISÃO DE FUTURO DA EMPRESA EM RELAÇÃO AOS PRÓXIMOS ANOS (3 A 5). EX: SER UMA REFERÊNCIA EM XYZ... | H6: POR QUE ESSE VALOR É IMPORTANTE PARA A EMPRESA?
H8: POR QUE ESSE VALOR É IMPORTANTE PARA A EMPRESA?
H10: POR QUE ESSE VALOR É IMPORTANTE PARA A EMPRESA?
H12: POR QUE ESSE VALOR É IMPORTANTE PARA A EMPRESA?
H14: POR QUE ESSE VALOR É IMPORTANTE PARA A EMPRESA?
H16: POR QUE ESSE VALOR É IMPORTANTE PARA A EMPRESA?

Sheet 1.2
B2: # | C2: << VOLTAR AO PAINEL DE CONTROLE | D2: MAPA DE CARGOS E FUNÇÕES
B4: # | C4: SÓCIA NATASHA | E4: # | F4: SÓCIO BRUNO | H4: # | I4: SOCIAL MEDIA (NOME DA PESSOA) | L4: # | M4: GESTOR DE TRAFEGO (NOME DA PESSOA) | P4: # | Q4: SOCIAL SELLER (NOME DA PESSOA)
B6: 1 | C6: LISTE AS FUNÇÕES DO CARGO | E6: 1 | F6: LISTE AS FUNÇÕES DO CARGO | H6: 1 | I6: LISTE AS FUNÇÕES DO CARGO | L6: 1 | M6: LISTE AS FUNÇÕES DO CARGO | P6: 1 | Q6: LISTE AS FUNÇÕES DO CARGO
B7: 2 | C7: LISTE AS FUNÇÕES DO CARGO | E7: 2 | F7: LISTE AS FUNÇÕES DO CARGO | H7: 2 | I7: LISTE AS FUNÇÕES DO CARGO | L7: 2 | M7: LISTE AS FUNÇÕES DO CARGO | P7: 2 | Q7: LISTE AS FUNÇÕES DO CARGO
B8: 3 | C8: LISTE AS FUNÇÕES DO CARGO | E8: 3 | F8: LISTE AS FUNÇÕES DO CARGO | H8: 3 | I8: LISTE AS FUNÇÕES DO CARGO | L8: 3 | M8: LISTE AS FUNÇÕES DO CARGO | P8: 3 | Q8: LISTE AS FUNÇÕES DO CARGO
B9: 4 | C9: LISTE AS FUNÇÕES DO CARGO | E9: 4 | F9: LISTE AS FUNÇÕES DO CARGO | H9: 4 | I9: LISTE AS FUNÇÕES DO CARGO | L9: 4 | M9: LISTE AS FUNÇÕES DO CARGO | P9: 4 | Q9: LISTE AS FUNÇÕES DO CARGO
B10: 5 | C10: LISTE AS FUNÇÕES DO CARGO | E10: 5 | F10: LISTE AS FUNÇÕES DO CARGO | H10: 5 | I10: LISTE AS FUNÇÕES DO CARGO | L10: 5 | M10: LISTE AS FUNÇÕES DO CARGO | P10: 5 | Q10: LISTE AS FUNÇÕES DO CARGO
B11: 6 | C11: LISTE AS FUNÇÕES DO CARGO | E11: 6 | F11: LISTE AS FUNÇÕES DO CARGO | H11: 6 | I11: LISTE AS FUNÇÕES DO CARGO | L11: 6 | M11: LISTE AS FUNÇÕES DO CARGO | P11: 6 | Q11: LISTE AS FUNÇÕES DO CARGO
B12: 7 | C12: LISTE AS FUNÇÕES DO CARGO | E12: 7 | F12: LISTE AS FUNÇÕES DO CARGO | H12: 7 | I12: LISTE AS FUNÇÕES DO CARGO | L12: 7 | M12: LISTE AS FUNÇÕES DO CARGO | P12: 7 | Q12: LISTE AS FUNÇÕES DO CARGO
B13: 8 | C13: LISTE AS FUNÇÕES DO CARGO | E13: 8 | F13: LISTE AS FUNÇÕES DO CARGO | H13: 8 | I13: LISTE AS FUNÇÕES DO CARGO | L13: 8 | M13: LISTE AS FUNÇÕES DO CARGO | P13: 8 | Q13: LISTE AS FUNÇÕES DO CARGO
B14: 9 | C14: LISTE AS FUNÇÕES DO CARGO | E14: 9 | F14: LISTE AS FUNÇÕES DO CARGO | H14: 9 | I14: LISTE AS FUNÇÕES DO CARGO | L14: 9 | M14: LISTE AS FUNÇÕES DO CARGO | P14: 9 | Q14: LISTE AS FUNÇÕES DO CARGO
B15: 10 | C15: LISTE AS FUNÇÕES DO CARGO | E15: 10 | F15: LISTE AS FUNÇÕES DO CARGO | H15: 10 | I15: LISTE AS FUNÇÕES DO CARGO | L15: 10 | M15: LISTE AS FUNÇÕES DO CARGO | P15: 10 | Q15: LISTE AS FUNÇÕES DO CARGO

Sheet 1.3
C2: < CLIQUE AQUI E VOLTE AO PAINEL INICIAL | D2: REGULAMENTO INTERNO
B4: # | C4: BLOCO | E4: PERGUNTAS PARA ANÁLISE | G4: ASSINALE O QUE VOCÊ IRÁ INSERIR NO SEU R.I.
B6: 1 | C6: INTRODUTÓRIO | E6: O regulamento interno da empresa é um documento em que está descrito um conjunto de direitos e deveres que tanto o empregador quanto os empregados devem seguir. | G6: X
B7: 2 | C7: INTRODUTÓRIO | E7: Neste bloco você deve inserir uma frase objetiva para cada um desses 3 pilares da sua empresa | G7: X
B8: 3 | C8: INTRODUTÓRIO | E8: Aqui você vai inserir o modelo de contratação: CLT, PJ, Freelancer, Temporário, Terceirizado, Home Office, Jovem Aprendiz, Estágio, etc | G8: X
B9: 4 | C9: UNIFORMES E EPI'S | E9: É indispensável o uso de uniforme completo por parte dos funcionários no interior da empresa e no caso de extravio ou de qualquer dano (por culpa do funcionário) o uniforme deverá ser ressarcido ao seu empregador. | G9: X
B10: 5 | C10: UNIFORMES E EPI'S | E10: Funções que exigem o uso de EPIs (Equipamentos de Proteção Individual), jamais podem ser exercidas sem que os funcionários estejam utilizando os itens obrigatórios. | G10: X
B11: 6 | C11: HORÁRIOS DE TRABALHO | E11: Os funcionários deverão se apresentar para o trabalho com cinco minutos de antecedência;
B12: 7 | C12: HORÁRIOS DE TRABALHO | E12: Os horários estabelecidos pelo Departamento de Pessoal (inclusive para café, almoço e lanche) deverão ser estritamente cumpridos, sob pena de descontos dos salários na razão do tempo de trabalho perdido;
B13: 8 | C13: HORÁRIOS DE TRABALHO | E13: O registro nos controles de frequência serão feitos por meio de ... (Ex: cartão de ponto) e os funcionários são obrigados a marcar cautelosamente as entradas e saídas, a fim de evitar registros errados.
B14: 9 | C14: HORÁRIOS DE TRABALHO | E14: O controle de frequência será verificado para monitorar as presenças, faltas e atrasos (neste caso serão procedidos descontos no salário);
B15: 10 | C15: HORÁRIOS DE TRABALHO | E15: As reincidências de ausências, ou atrasos ao serviço, sem causa justificada, constituem motivo passível de rescisão do Contrato de Trabalho por justa causa;
B16: 11 | C16: HORÁRIOS DE TRABALHO | E16: É necessária a apresentação de atestado médico para abono de faltas e atrasos nas rotinas de trabalho;
B17: 12 | C17: HORÁRIOS DE TRABALHO | E17: As saídas antecipadas somente serão permitidas, com a devida autorização do responsável pelo Departamento e, após a marcação do cartão de ponto;
B18: 13 | C18: HORÁRIOS DE TRABALHO | E18: Inserir como funciona as escalas e quando o colaborador poderá gozar do seu dia de folga
B19: 14 | C19: HORÁRIOS DE TRABALHO | E19: As férias devem ser solicitadas e aprovadas previamente pela liderança imediata do funcionário (com antecedência de X meses);
B20: 15 | C20: ROTINAS INTERNAS | E20: O funcionário não pode permanecer sem o uniforme durante as atividades na empresa ou em serviços fora da empresa;
B21: 16 | C21: ROTINAS INTERNAS | E21: O funcionário não pode recusar-se a assinar o cartão de ponto ou o controle de horas trabalhadas;
B22: 17 | C22: ROTINAS INTERNAS | E22: O funcionário não pode ausentar-se dos departamentos ou seções onde trabalha, sem prévia autorização dos seus chefes;
... B43: 38 | C43: PROMOÇÕES NA CARREIRA | E43: É um diferencial saber trabalhar sob pressão, seja para cumprir os prazos de entrega, atender clientes difíceis, lidar com conflitos no dia a dia e agir de forma madura e profissional.

Sheet 1.5
B2: # | C2: < CLIQUE AQUI E VOLTE AO PAINEL INICIAL | D2: REUNIÃO NOTA 10 (DIÁRIA OU SEMANAL)
B4: # | C4: NOME DA PESSOA | E4: # | F4: NOME DA PESSOA | H4: # | I4: NOME DA PESSOA | L4: # | M4: NOME DA PESSOA | P4: # | Q4: NOME DA PESSOA
C6: AÇÃO PARA SER EXECUTADA ESCRITA COM VERBO NO INFINITIVO E QUE SEJA DE RESPONSABILIDADE DA PESSOA OU DO TIME DA PESSOA, POIS ELA SERÁ COBRADA NO DIA SEGUINTE | F6: AÇÃO PARA SER EXECUTADA ESCRITA COM VERBO NO INFINITIVO E QUE SEJA DE RESPONSABILIDADE DA PESSOA OU DO TIME DA PESSOA, POIS ELA SERÁ COBRADA NO DIA SEGUINTE | I6: AÇÃO PARA SER EXECUTADA ESCRITA COM VERBO NO INFINITIVO E QUE SEJA DE RESPONSABILIDADE DA PESSOA OU DO TIME DA PESSOA, POIS ELA SERÁ COBRADA NO DIA SEGUINTE | M6: AÇÃO PARA SER EXECUTADA ESCRITA COM VERBO NO INFINITIVO E QUE SEJA DE RESPONSABILIDADE DA PESSOA OU DO TIME DA PESSOA, POIS ELA SERÁ COBRADA NO DIA SEGUINTE | Q6: AÇÃO PARA SER EXECUTADA ESCRITA COM VERBO NO INFINITIVO E QUE SEJA DE RESPONSABILIDADE DA PESSOA OU DO TIME DA PESSOA, POIS ELA SERÁ COBRADA NO DIA SEGUINTE
B7: 1 | E7: 1 | H7: 1 | L7: 1 | P7: 1
B8: 2 | E8: 2 | H8: 2 | L8: 2 | P8: 2
B9: 3 | E9: 3 | H9: 3 | L9: 3 | P9: 3

Sheet 1.6
C2: < CLIQUE AQUI E VOLTE AO PAINEL INICIAL | D2: ANÁLISE DE RESULTADOS MENSAIS
D4: INDICADOR ANALISADO | F4: META | G4: REALIZADO | H4: DESVIO | I4: FAROL
D6: VENDAS NO AÇOUGUE | F6: 100000 | G6: 90000 | H6: =F6-G6 -> 10000 | I6: n
D8: Causa Primária | E8: Causa 2 | F8: Causa 3 | G8: Causa 4 | H8: Causa 5 | I8: Causa Raiz
D9: TICKET MEDIO NÃO BATEU A META | E9: ERA PRA ALCANÇAR 50 E FICAMOS EM 45 | F9: AÇOUGUEIRO NÃO ATENDEU CORRETAMENTO OS CLIENTES | G9: NÃO HÁ UM SCRIPT DE ATENDIMENTO E NEM TREINAMENTO DOS AÇOUGUEIROS
D11: Ação Corretiva | H11: Quem | I11: Prazo
D12: CRIAR SCRIPT E TREINAR OS AÇOUGUEIROS PARA AUMENTAR AS OFERTAS OFERECENDO ITENS CORRELACIONADOS PARA INCREMENTAR O TICKET MÉDIO | H12: DANIEL REICHE | I12: 45688

Sheet 1.7
C2: < CLIQUE AQUI E VOLTE AO PAINEL INICIAL | D2: CRIAÇÃO DE CULTURA FORTE | M2: NOTA DA AVALIAÇÃO > | P2: =AVERAGE(H6,H7,H8,H9,H10,P6,P7,P8,P9,P10) -> 6.5
D4: # | F4: TÓPICO ANALISADO | H4: NOTA ATUAL | K4: # | M4: TÓPICO ANALISADO | P4: NOTA ATUAL
D6: 1 | F6: DEFINIR E COMUNICAR A MISSÃO, VISÃO E VALORES NO DIA A DIA (QUADROS, PAREDES, PROTEÇÃO DE TELA, ETC) | H6: 5 | K6: 6 | M6: DEFINIÇÃO DE METAS, PROPÓSITOS CLAROS E AÇÕES CONCRETAS (FOCO EM RESULTADO) | P6: 4
D7: 2 | F7: PROMOVER TREINAMENTOS ESPECÍFICOS PARA MEMBROS DA EQUIPE (ESTÍMULO PARA CARGOS E HABILIDADES ESPECÍFICAS) | H7: 6 | K7: 7 | M7: REUNIÃO DE ALINHAMENTO DIÁRIO, SEMANAL E MENSAL (ALINHAMENTO DE EXPECTATIVAS E PRIORIDADES SEMPRE) | P7: 6
D8: 3 | F8: PROMOVER EVENTOS ABERTOS AO TIME (ANIVERSÁRIO DA EMPRESA, SEMANA DA QUALIDADE, DIA DE REFORÇO DOS PILARES DA CULTURA) | H8: 7 | K8: 8 | M8: COMEMORAÇÃO POR METAS BATIDAS COM A EQUIPE (PASSEIOS, RESTAURANTES, FESTAS, ETC) | P8: 5
D9: 4 | F9: REALIZAR PESQUISA DE CLIMA ORGANIZACIONAL (ESTRATÉGIA OBRIGATÓRIA PARA FORTALECER A CULTURA) | H9: 8 | K9: 9 | M9: COMEMORAÇÃO EM DATAS ESPECIAIS (DIA DO TRABALHO, DIA DA MULHER, DIA DAS MÃES, DIA DOS PAIS, DAY OFF (FOLGA) NO ANIVERSÁRIO | P9: 7
D10: 5 | F10: PROMOVER COMUNICAÇÃO INTERNA (E-MAILS, NEWSLETTER, COMUNICADOS, ALINHAMENTO COM FUNCIONÁRIOS, FORNECEDORES E CLIENTES) | H10: 9 | K10: 10 | M10: FEEDBACKS INDIVIDUAIS COM O TIME (REFORÇO ESPECÍFICO AOS PILARES COM BASE NOS COMPORTAMENTOS DE CADA PESSOA) | P10: 8

Sheet 1.8
C2: < CLIQUE AQUI E VOLTE AO PAINEL INICIAL | E2: REMUNERAÇÃO VARIÁVEL
C4: >>>>>>> Tabela para projetar o valor que será pago em bônus para todo o time após 1 ano de trabalho >>>>>>>> | E4: Cargos | F4: Bônus em Número de Salários / Ano (Referência de Mercado) | G4: Bônus em Número de Salários / Ano (Ex: Para minha empresa) | H4: # Colaboradores na minha empresa hoje | I4: R$ Salário pago na minha empresa hoje | J4: R$ Bônus previsto a ser pago
E5: Júnior | F5: 1 | G5: 1 | H5: 3 | I5: 2000 | J5: =G5*H5*I5 -> 6000
E6: Pleno | F6: 2 | G6: 1 | H6: 2 | I6: 3000 | J6: =G6*H6*I6 -> 6000
E7: Sênior | F7: 3 | G7: 1 | H7: 2 | I7: 5000 | J7: =G7*H7*I7 -> 10000
E8: Coordenador/Supervisor | F8: 4 | G8: 1 | H8: 2 | I8: 8000 | J8: =G8*H8*I8 -> 16000
E9: Head/Gerente | F9: 6 | G9: 1 | H9: 2 | I9: 10000 | J9: =G9*H9*I9 -> 20000
E10: Diretor | F10: 12 | G10: 1 | H10: 1 | I10: 20000 | J10: =G10*H10*I10 -> 20000
E11: Total | F11: - | G11: - | H11: =SUM(H5:H10) -> 12 | I11: - | J11: =SUM(J5:J10) -> 78000
E13: Quanto quero distribuir após um ano? > | J13: =J11 -> 78000 | K13: < Célula preenchida automaticamente
E15: Qual meu lucro anual estimado após um ano? > | J15: 1000000 | K15: < Digite aqui o valor que você espera lucrar em 12 meses
E17: Qual % que será distribuído se as estimativas acima estiverem certas? > | J17: =J13/J15 -> 0.078 | K17: < Célula preenchida automaticamente

Sheet 2.1
B2: < CLIQUE AQUI E VOLTE AO PAINEL INICIAL | D2: RAIO-X DO CLIENTE DOS SONHOS
B4: DORES | D4: DESEJOS | F4: CRENÇAS | H4: OBJEÇÕES
B6: DIGITE AQUI UMA DOR ESPECÍFICA QUE SEU CLIENTE DOS SONHOS POSSUI DIARIAMENTE E VOCÊ PODE SOLUCIONAR | D6: DIGITE AQUI UM DESEJO ESPECÍFICO QUE SEU CLIENTE DOS SONHOS POSSUI DIARIAMENTE E VOCÊ PODE REALIZAR | F6: DIGITE AQUI UMA CRENÇA LIMITANTE SOBRE SEU PRODUTO OU SERVIÇO QUE SEU CLIENTE POSSUI E VOCÊ PRECISA COMBATER DIARIAMENTE | H6: DIGITE AQUI UMA OBJEÇÃO QUE SEU CLIENTE DOS SONHOS POSSUI DIARIAMENTE E VOCÊ PODE SOLUCIONAR
B7: "NÃO CONSIGO FAZER MINHA EMPRESA FUNCIONAR SEM DEPENDER DE MIM" | D7: "QUERO PODER TIRAR FÉRIAS DA MINHA EMPRESA, MAS ESTOU PRESO(A) NA OPERAÇÃO" | F7: "NÃO ACHO QUE UMA MENTORIA VAI AJUDAR MINHA EMPRESA A MUDAR" | H7: "NÃO TENHO DINHEIRO AGORA, MAS QUANDO TIVER, EU ENTRO PARA SUA MENTORIA"
B8: "NÃO CONFIO NO MEU TIME E TENHO QUE CONFERIR TUDO QUE PEÇO PARA OS FUNCIONÁRIOS" | D8: "QUERO CUIDAR MELHOR DA MINHA FAMÍLIA, MAS MINHA EMPRESA NÃO PERMITE" | F8: "ESTUDAR ONLINE NÃO É PRA MIM E NÃO VAI ME AJUDAR EM MEU NEGÓCIO" | H8: "NÃO TENHO TEMPO PARA ME DEDICAR E ESTUDAR COMO DEVERIA PARA SUA MENTORIA"
B9: "NÃO ACHO GENTE BOA PARA TRABALHAR E CADA DIA ESTÁ MAIS DIFÍCIL CONTRATAR FUNCIONÁRIOS" | D9: "QUERO CUIDAR DA MINHA SAÚDE, MAS NÃO SOBRA TEMPO DE IR PRA ACADEMIA" | F9: "ESTOU VELHO PARA COMEÇAR A ME CAPACITAR NOVAMENTE" | H9: "NÃO ESTOU NO MOMENTO CERTO PRA ENTRAR, PORQUE PRECISO ME ORGANIZAR PRIMEIRO"
B10: "NÃO TENHO UMA EQUIPE ENGAJADA, PROATIVA E COM ATITUDE DE DONO NO DIA A DIA DA EMPRESA" | D10: "QUERO TER UM EMPRESA QUE FUNCIONE COMIGO POR PERTO OU MESMO SEM A MINHA PRESENÇA" | F10: "NO MEU CASO ESPECÍFICO, PRO MEU NICHO, EU ACHO QUE ISSO NÃO FUNCIONA" | H10: "NÃO TENHO LIMITE NO CARTÃO PARA FAZER O PAGAMENTO AGORA"
B11: "NÃO VEJO O RETORNO FINANCEIRO QUE GOSTARIA DE VER, MESMO TRABALHANDO MUITO DURO" | D11: "QUERO PODER GARANTIR MINHA INDEPENDÊNCIA FINANCEIRA E DOS MEUS FILHOS" | F11: "ACHO QUE JÁ ATINGI MEU POTENCIAL MÁXIMO COM MINHA EMPRESA" | H11: "PRECISO FALAR COM MEU SÓCIO(A) E DEPOIS TE DOU UM RETORNO"
B13: DORES | D13: DESEJOS | F13: CRENÇAS | H13: OBJEÇÕES

Sheet 2.2
B2: < CLIQUE AQUI E VOLTE AO PAINEL INICIAL | D2: CRIAÇÃO DE CONTEÚDOS | J2: 70 HEADLINES PARA POSTS QUE ENGAJAM
B4: DORES | D4: DESEJOS | F4: CRENÇAS | H4: OBJEÇÕES
B6: DIGITE AQUI UMA DOR ESPECÍFICA QUE SEU CLIENTE DOS SONHOS POSSUI DIARIAMENTE E VOCÊ PODE SOLUCIONAR | D6: DIGITE AQUI UM DESEJO ESPECÍFICO QUE SEU CLIENTE DOS SONHOS POSSUI DIARIAMENTE E VOCÊ PODE REALIZAR | F6: DIGITE AQUI UMA CRENÇA LIMITANTE SOBRE SEU PRODUTO OU SERVIÇO QUE SEU CLIENTE POSSUI E VOCÊ PRECISA COMBATER DIARIAMENTE | H6: DIGITE AQUI UMA OBJEÇÃO QUE SEU CLIENTE DOS SONHOS POSSUI DIARIAMENTE E VOCÊ PODE SOLUCIONAR | J6: 1. Se você age assim olha o que acontece | K6: 11. Sem saber isso você não consegue (objetivo do seu avatar) | L6: 21. Se você quer (objetivo do avatar), este é o caminho | M6: 31. Não é (algo que o seu avatar acredita que é a solução) que traz resultado. É isso aqui! | N6: 41. Quem está (situação comum do seu avatar) é por que ainda não percebeu/aprendeu/descobriu isso | O6: 51. Os segredos por trás de (algo do seu nicho) | P6: 61. Por que eu não recomendo que você (atitude ineficaz comum do seu avatar)
B7: "NÃO CONSIGO FAZER MINHA EMPRESA FUNCIONAR SEM DEPENDER DE MIM" | D7: "QUERO PODER TIRAR FÉRIAS DA MINHA EMPRESA, MAS ESTOU PRESO(A) NA OPERAÇÃO" | F7: "NÃO ACHO QUE UMA MENTORIA VAI AJUDAR MINHA EMPRESA A MUDAR" | H7: "NÃO TENHO DINHEIRO AGORA, MAS QUANDO TIVER, EU ENTRO PARA SUA MENTORIA" | J7: 2. Este é pra quem tem/faz (erro comum do avatar) | K7: 12. Mais um segredo do (algo do seu nicho) que muita gente não sabe | L7: 22. Se você já (erro comum), veja esse vídeo | M7: 32. Assim que você faz (objetivo do seu avatar) sem precisar (objeção do avatar) | N7: 42. Enquanto você não (atitude que seu avatar desconsidera) você não vai (objetivo do seu avatar) | O7: 52. Você pensa que é difícil (resultado desejado) mas assim fica bem mais fácil | P7: 62. Aplique isso e seus resultados vão explodir
B8: 3 ERROS QUE IMPEDEM SUA EMPRESA DE FUNCIONAR SEM VOCÊ | D8: VOCÊ NUNCA VAI TIRAR FÉRIAS SE COMETER ESSES 4 ERROS | F8: COMO A MENTORIA MUDOU MINHA EMPRESA EM X MESES | H8: SE SUA EMPRESA ESTÁ SEM DINHEIRO VOCÊ PODE ESTAR ERRANDO NESSES PONTOS... | J8: 3. Aposto que você pensa que (pensamento comum do avatar) | K8: 13. Isso é o que meus alunos fazem para (resultado obtido no seu curso) | L8: 23. Estou (situação indesejada comum do seu avatar). O que eu faço? | M8: 33. Vou te provar que (algo que seu avatar não acredita) | N8: 43. Essa é pra você que precisa (objetivo do avatar) | O8: 53. Por que eu não acredito que (ação ineficaz comum do seu avatar para chegar ao resultado) dá certo | P8: 63. Fazer tal coisa ou fazer tal coisa, o que é melhor pra você? (dúvida comum do seu avatar)
B9: SUA EMPRESA FUNCIONARÁ SEM VOCÊ DEPOIS DESSA ÚNICA AÇÃO | D9: EMPRESÁRIOS COM FÉRIAS DE 30 DIAS AO ANO, FAZEM EXATAMENTE ISSO | F9: DEPOIS DA MENTORIA, ESSE FOI O RESULTADO QUE EU TIVE | H9: QUANDO ANTES VOCÊ SOUBER DISSO, MENOS DINHEIRO VOCÊ PERDE NA SUA EMPRESA | J9: 4. Se te dizem que (objeção comum do avatar) então veja esse vídeo | K9: 14. Entenda o que (tema do seu nicho) tem a ver com (algo que seu avatar não sabe) | L9: 24. É isso que te falta para (objetivo do seu avatar) | M9: 34. Duvido que depois desse vídeo você ainda pense que (algo que seu avatar acredita) | N9: 44. Essa é o problema de (comportamento comum do seu avatar) | O9: 54. Definitivamente desse jeito você não vai conseguir (resultado desejado) | P9: 64. Talvez seja por isso que você não consegue (resultado desejado).
B10: EMPRESÁRIOS COM LIBERDADE, NÃO COMETEM ESSES ERROS | D10: TREINE SUA EQUIPE DESSA FORMA E TENHA FÉRIAS TODOS OS ANOS | F10: EMPRESÁRIOS QUE TEM MENTORES AVANÇAM MUITO POR CAUSA DESSE DIFERENCIAL... | H10: SE SUA EMPRESA VIVE SEM DINHEIRO, VEJA ESSE VÍDEO AGORA | J10: 5. Quando (grupo do seu avatar – mulheres, autônomo, pais) descobrem isso, é um choque! | K10: 15. Você também precisa olhar para (algo do seu nicho) assim | L10: 25. Assista a esse vídeo se você quer (objetivo do seu avatar) | M10: 35. É isso que acontece quando (erro comum do avatar) | N10: 45. É possível evitar (resultado indesejado comum) assim | O10: 55. O motivo pelo qual você não consegue (resultado desejado) | P10: 65. O ponto chave para (resultado desejado)
B11: "NÃO CONFIO NO MEU TIME E TENHO QUE CONFERIR TUDO QUE PEÇO PARA OS FUNCIONÁRIOS" | D11: "QUERO CUIDAR MELHOR DA MINHA FAMÍLIA, MAS MINHA EMPRESA NÃO PERMITE" | F11: "ESTUDAR ONLINE NÃO É PRA MIM E NÃO VAI ME AJUDAR EM MEU NEGÓCIO" | H11: "NÃO TENHO TEMPO PARA ME DEDICAR E ESTUDAR COMO DEVERIA PARA SUA MENTORIA" | J11: 6. Como fazer para (objetivo do avatar) sem ter que (objeção do avatar) | K11: 16. É assim que você descobre como começar | L11: 26. Quem fez isso conseguiu (objetivo do seu avatar) | M11: 36. Entre tal coisa e tal coisa você deve começar por... (dúvida comum do seu avatar) | N11: 46. A forma mais efetiva de (resultado desejado) | O11: 56. A ideia mais incrível para quem quer (resultado indesejado) | P11: 66. Você não precisa ser (comportamento comum) para (resultado desejado)
B12: SE VOCÊ NÃO CONFIA NA SUA EQUIPE, ESSE VÍDEO É PRA VOCÊ | D12: EU FIZ ESSAS 4 COISAS PRA CONSEGUIR TOCAR MINHA EMPRESA E TER TEMPO PRA MINHA FAMÍLIA | F12: SE VOCÊ TEM EMPRESA E NÃO SABE ONDE BUSCAR AJUDA PRA CRESCER, ASSISTA ISSO | H12: SE VOCÊ SENTE QUE NÃO TEM TEMPO PRA NADA, ESCUTE ESSE VÍDEO ATÉ O FIM | J12: 7. Se você está fazendo isso está cometendo um grande erro | K12: 17. Eu fiz essas X coisas para conseguir (resultado que seu avatar quer) | L12: 27. Se você é assim, então melhor nem ver esse vídeo | M12: 37. Você quer ter ânimo para (algo que ele procrastina)? | N12: 47. O melhor jeito de (resultado desejado) sem (objeção) | O12: 57. A sacada mais eficaz para quem não sabe (resultado desejado) | P12: 67. O risco escondido em (comportamento comum)
B13: QUEM FEZ ISSO, CONSEGUIU DELEGAR E PARAR DE CONFERIR TUDO | D13: SE VOCE NÃO FIZER ISSO NA SUA EMPRESA, OLHA O QUE ACONTECE NA SUA FAMÍLIA | F13: ESSA É PRA EMPRESÁRIOS QUE COMEÇARAM NA CARA E NA CORAGEM SEM ESTUDO ALGUM | H13: A FORMA MAIS EFETIVA PARA EMPRESÁRIOS SEM TEMPO PROSPERAREM É ESSA | J13: 8. Essa é pra quem (comportamento comum do avatar) e não sabe como resolver | K13: 18. É por isso que você não precisa (objeção do seu avatar) | L13: 28. Se você não fizer (algo que avatar está procrastinando), olha o que acontece | M13: 38. Quanto mais você fizer isso, mais vai conseguir (objetivo do avatar) | N13: 48. O que eu penso quando me dizem que (frase repetida pelo seu avatar) | O13: 58. Um guia rápido para (resultado desejado) | P13: 68. Consiga (resultado desejado) sem perder (algo que seu avatar não quer perder)
B14: É ISSO QUE FALTA PRA VOCÊ PARAR DE CONFERIR O TRABALHO DOS SEUS FUNCIONÁRIOS | D14: É ISSO QUE TE FALTA PRA TER UMA EMPRESA LUCRATIVA SEM AFETAR SUA FAMILIA | F14: É POR ISSO QUE SUA EMPRESA PAROU DE CRESCER E ESTAGNOU | H14: ESSE VIDEO VAI TE SALVAR DA ARMADILHA QUE É NÃO BUSCAR MENTORES PARA SUA EMPRESA | J14: 9. Essa é pra quem (comportamento comum do avatar) e quer muito mudar | K14: 19. É assim que se faz para (resultado que seu avatar quer) | L14: 29. É por isso que (algo que seu avatar acha que é a solução) não funciona | M14: 39. Essa é pra quem está (frustrado, desesperado, tenso) com (situação comum do seu avatar) | N14: 49. Use isso na hora de (situação corriqueira do seu avatar) | O14: 59. Aprenda isso antes de querer (algo que seu avatar quer ou está fazendo) | P14: 69. Se livre de (problema) de uma vez por todas.
B15: "NÃO ACHO GENTE BOA PARA TRABALHAR E CADA DIA ESTÁ MAIS DIFÍCIL CONTRATAR FUNCIONÁRIOS" | D15: "QUERO CUIDAR DA MINHA SAÚDE, MAS NÃO SOBRA TEMPO DE IR PRA ACADEMIA" | F15: "ESTOU VELHO PARA COMEÇAR A ME CAPACITAR NOVAMENTE" | H15: "NÃO ESTOU NO MOMENTO CERTO PRA ENTRAR, PORQUE PRECISO ME ORGANIZAR PRIMEIRO" | J15: 10. Essa atitude fez muita diferença na minha vida | K15: 20. Se você quiser de verdade, você consegue fazendo isso! | L15: 30. Esse vídeo vai te salvar dessa armadilha. Ou “Esse vídeo vai te salvar da armadilha de (algo que acontece com seu avatar) | M15: 40. A única maneira de (objetivo do seu avatar) é essa | N15: 50. A verdade oculta sobre (algo do seu nicho) | O15: 60. A pior maneira de (resultado desejado) | P15: 70. O quanto antes você souber isso melhor.
B16: QUANTO ANTES VOCE SOUBER DESSES 3 PONTOS, MAIS GENTE BOA VIRÁ PRA SUA EMPRESA | D16: VOCÊ PRECISA FAZER ISSO PRA SER UM EMPRESÁRIO DE SUCESSO SEM DESTRUIR SUA SAÚDE | F16: ESSA SITUAÇÃO FEZ MUITA DIFERENÇA, MESMO SENDO EMPRESÁRIO HÁ MAIS DE X ANOS... (PROVA SOCIAL) | H16: QUEM TENTOU SE ORGANIZAR SOZINHO PRA DEPOIS BUSCAR AJUDA PRA SUA EMPRESA, SOFREU ASSIM...
B17: É POR ESSE FATOR QUE VOCÊ NÃO CONSEGUE CONTRATAR BONS FUNCIONÁRIOS | D17: SE VOCÊ É EMPRESÁRIO E NÃO TEM TEMPO DE IR PRA ACADEMIA, DEVE ESTAR ERRANDO NISSO | F17: EU NÃO SEI COMO EU CHEGUEI ATÉ AQUI SEM CONHECER O...(NOME DA SOLUÇÃO/ MENTOR) (PROVA SOCIAL) | H17: O MELHOR JEITO DE CRESCER SUA EMPRESA NÃO É TENTANDO ORGANIZAR ELA SOZINHO E SIM....
B18: ESSA É PRA QUEM ACHA QUE NÃO TEM MÃO DE OBRA QUALIFICADA NA SUA CIDADE | D18: ENTRE SUA EMPRESA E SUA SAÚDE, VOCE NÃO PRECISA ESCOLHER 1 COISA SÓ. BASTA DOMINAR ISSO! | F18: VOCE QUER TER ANIMO PRA EMPREENDER E JÁ TEM MAIS DE X ANOS? ASSISTA ESSE VIDEO! | H18: VOU TE PROVAR QUE SE VOCÊ TENTAR ORGANIZAR SUA EMPRESA SOZINHO, VOCÊ PERDERÁ TEMPO
B19: "NÃO TENHO UMA EQUIPE ENGAJADA, PROATIVA E COM ATITUDE DE DONO NO DIA A DIA DA EMPRESA" | D19: "QUERO TER UM EMPRESA QUE FUNCIONE COMIGO POR PERTO OU MESMO SEM A MINHA PRESENÇA" | F19: "NO MEU CASO ESPECÍFICO, PRO MEU NICHO, EU ACHO QUE ISSO NÃO FUNCIONA" | H19: "NÃO TENHO LIMITE NO CARTÃO PARA FAZER O PAGAMENTO AGORA"
B20: APRENDA ISSO E TENHA UMA EQUIPE SUPER ENGAJADA | D20: ESSE É O PROBLEMA PRINCIPAL DE EMPRESÁRIOS PRESOS NA OPERAÇÃO | F20: VEJA O QUE A EMPRESA DE ..... OBTEVE APÓS NOSSA METODOLOGIA SER IMPLEMENTADA | H20: SE O LIMITE DO SEU CARTÃO É BAIXO E VOCE É DONO DE EMPRESA, ESCUTE ATÉ O FINAL
B21: VOU TE PROVAR QUE UMA EQUIPE PROATIVA NÃO SE CRIA SOMENTE PAGANDO MELHOR | D21: EU FIZ ESSAS X COISAS PARA MINHA EMPRESA FUNCIONAR SEM MIM | F21: ELE É ......E CONSEGUIU CRESCER X% APÓS EXECUTAR ESSA ÚNICA AÇÃO | H21: DUVIDO QUE DEPOIS DESSE VIDEO VOCE VAI CONTINUAR ACHANDO QUE NÃO CONSEGUE SER NOSSO CLIENTE...
B22: ESSE É UM SEGREDO DAS EQUIPES DE ALTA PERFORMANCE QUE VOCÊ JAMAIS PENSOU | D22: VOCÊ NÃO PRECISA TRABALHAR 16 HORAS PARA SUA EMPRESA FUNCIONAR SE SOUBER DISSO... | F22: PRA VOCE QUE TAMBEM É ......VEJA ESSE RESULTADO SURPREENDENTE | H22: APOSTO QUE VOCE PENSA QUE NÃO CONSEGUE COMPRAR ..... MAS EU VOU TE PROVAR QUE...
B23: "NÃO VEJO O RETORNO FINANCEIRO QUE GOSTARIA DE VER, MESMO TRABALHANDO MUITO DURO" | D23: "QUERO PODER GARANTIR MINHA INDEPENDÊNCIA FINANCEIRA E DOS MEUS FILHOS" | F23: "ACHO QUE JÁ ATINGI MEU POTENCIAL MÁXIMO COM MINHA EMPRESA" | H23: "PRECISO FALAR COM MEU SÓCIO(A) E DEPOIS TE DOU UM RETORNO"
B24: 3 LADRÕES DE LUCRO QUE TODO EMPRESÁRIO DEVE COMBATER | D24: DEFINITIVAMENTE DESSE JEITO, VOCÊ NÃO SERÁ UM EMPRESÁRIO RICO | F24: É ASSIM QUE VOCE DESCOBRE SE SUA EMPRESA JÁ ATINGIU O POTENCIAL MÁXIMO OU NÃO | H24: SOMENTE HOJE, QUEM FECHAR CONOSCO TERÁ ACESSO AO BONUS X
B25: A VERDADE OCULTA SOBRE EMPRESAS QUE VIVEM NO VERMELHO | D25: ESSAS 2 ATITUDES FIZERAM MINHA EMPRESA GERAR RIQUEZA ABUNDANTE | F25: ESSE É O PONTO CHAVE PRA QUEM ESTÁ COM A EMPRESA ESTAGNADA | H25: ASSISTA ESSE VIDEO SE VOCE AINDA TEM DUVIDAS SOBRE O PRODUTO XYZ...
B26: NÃO VEJO O LUCRO DO MEU NEGÓCIO. O QUE EU FAÇO? | D26: A VERDADE OCULTA SOBRE EMPRESAS MULTI MILIONÁRIAS | F26: O GRANDE RISCO PARA EMPRESAS QUE PARARAM DE CRESCER É ... | H26: QUEM COMPRAR AMANHÃ E NÃO HOJE, PERDERÁ OS BONUS XYZ....

Sheet 2.3
B2: < CLIQUE AQUI E VOLTE AO PAINEL INICIAL | C2: FUNIL DE PROSPECÇÃO ATIVA PELO DIRECT (SOCIAL SELLER)
B4: 1 | C4: IDENTIFICAÇÃO DO PERFIL DO LEAD QUALIFICADO (MQL ou CDP)
B5: 2 | C5: QUAIS AS CARACTERÍSTICAS DA PERSONA DO MEU PRODUTO? (EX: DONO DE EMPRESA, COM MINIMO DE 10 FUNCIONÁRIOS, VIDA E FAMÍLIA ESTRUTURADA, VIAGENS, FÉRIAS, ETC)
B6: 3 | C6: QUAIS ELEMENTOS DA REDE SOCIAL VOU USAR NO CHECKLIST DA MINHA PERSONA? (FOTO,Nº PUBLICAÇÕES, Nº DE SEGUIDORES,INFO NA BIO, SEGUIDORES EM COMUM...)
B7: 4 | C7: IDENTIFICAÇÃO DA LINGUAGEM QUE SERÁ UTILIZADA COM O LEAD
B8: 5 | C8: QUAL O TOM DE VOZ QUE A SUA MARCA SE COMUNICA? (HUMOR, DESCOLADO, FORMAL)
B9: 6 | C9: QUAIS EXPRESSÕES E TERMOS PADRÕES DA COMUNICAÇÃO DA MARCA (JARGÃO, FRASE, PALAVRAS CHAVE)
B10: 7 | C10: QUAIS EXPRESSÕES E TERMOS NÃO USAR (DO CONCORRENTE)
B11: 8 | C11: CRIAÇÃO DE LISTA DE CONTROLE DE ABORDAGENS
B12: 9 | C12: REGISTRAR DADOS PARA GERENCIAR ESTE LEAD (NOME, @, CIDADE, CLASSIFICAÇÃO, DATA DE CONTATO, DE QUAL POST)
B13: 10 | C13: DEFINIR PERIODICIDADE DOS CONTATOS E MONITORAR LEADS SEM CONTATO A "X DIAS"
B14: 11 | C14: ELABORAÇÃO DE CONTEÚDOS INTENCIONAIS PARA GERAR INTERAÇÃO ("LEVANTADA DE MÃO")
B15: 12 | C15: MAPEAR AS DORES, DESEJOS, CRENÇAS LIMITANTES E OBJEÇÕES DO MEU CLIENTE DOS SONHOS
... B49: 46 | C49: SE SIM: ENVIAR LINK DE FORMULÁRIO OU SOLICITAR CONEXÃO VIA WHATSAPP PARA ABRIR PROCESSO DE ATENDIMENTO INDIVIDUAL
B50: FIM

Sheet 2.4
B2: < CLIQUE AQUI E VOLTE AO PAINEL INICIAL | C2: LIVE SHOP
B4: 1
B5: 2
B6: 3
B7: 4
B8: 5
B9: 6
B10: 7
B11: 8
B12: 9
B13: 10
B14: 11
B15: 12
... B49: 46
B50: FIM

Sheet 3.1
B2: < CLIQUE AQUI E VOLTE AO PAINEL INICIAL | C2: AMPULHETA DE VENDAS (MÉDIA GERAL) > | H2: =(D26+H26)/2 -> 6.6
B4: FASE | C4: PERGUNTA | D4: NOTA DE 0 A 10 | E4: MÉDIA | F4: FASE | G4: PERGUNTA | H4: NOTA DE 0 A 10 | I4: MÉDIA
B5: PROSPECÇÃO | C5: 1.1 VOCÊ ESTÁ AONDE O SEU CLIENTE FAZ BUSCAS E ESTÁ PROCURANDO? | D5: 10 | E5: =AVERAGE(D5:D9) -> 8 | F5: PÓS VENDA | G5: 5.1 SEU CLIENTE RECEBE CONTATOS APÓS EFETUAR A COMPRA PRA SABER SE ESTÁ TUDO OK? | H5: 9 | I5: =AVERAGE(H5:H9) -> 8.2
C6: 1.2 VOCÊ POSSUI UMA BUSCA ATIVA PELO SEU CLIENTE? | D6: 9 | G6: 5.2 SEU CLIENTE É PROVOCADO(A) PARA QUE FORNEÇA FEEDBACKS? | H6: 9
C7: 1.3 VOCÊ BUSCA DE FORMA AUTOMÁTICA, ATRAVÉS DE TRÁFEGO PAGO FOCADO NA DOR? | D7: 8 | G7: 5.3 SUA TAXA DE CONVERSÃO É MEDIDA (LEADS OBTIDOS X VENDAS REALIZADAS)? | H7: 8
